INFO 2025-08-28 16:17:05,127 autoreload 47060 39584 Watching for file changes with StatReloader
INFO 2025-08-28 16:22:16,014 autoreload 47060 39584 C:\Local Disk E\BlitzTech Systems\erpdev\blitzhub\settings.py changed, reloading.
INFO 2025-08-28 16:22:17,942 autoreload 20124 14992 Watching for file changes with StatReloader
INFO 2025-08-28 16:25:01,066 autoreload 20124 14992 C:\Local Disk E\BlitzTech Systems\erpdev\blitzhub\settings.py changed, reloading.
INFO 2025-08-28 16:25:03,570 autoreload 46640 44800 Watching for file changes with StatReloader
ERROR 2025-08-28 16:25:13,029 log 46640 32640 Internal Server Error: /
Traceback (most recent call last):
  File "C:\Local Disk E\BlitzTech Systems\erpdev\venv\lib\site-packages\django\utils\module_loading.py", line 30, in import_string
    return cached_import(module_path, class_name)
  File "C:\Local Disk E\BlitzTech Systems\erpdev\venv\lib\site-packages\django\utils\module_loading.py", line 16, in cached_import
    return getattr(module, class_name)
AttributeError: module 'core.context_processors' has no attribute 'site_settings'

The above exception was the direct cause of the following exception:

Traceback (most recent call last):
  File "C:\Local Disk E\BlitzTech Systems\erpdev\venv\lib\site-packages\django\core\handlers\exception.py", line 55, in inner
    response = get_response(request)
  File "C:\Local Disk E\BlitzTech Systems\erpdev\venv\lib\site-packages\django\core\handlers\base.py", line 197, in _get_response
    response = wrapped_callback(request, *callback_args, **callback_kwargs)
  File "C:\Local Disk E\BlitzTech Systems\erpdev\website\views.py", line 59, in home
    return render(request, 'website/index.html', context)
  File "C:\Local Disk E\BlitzTech Systems\erpdev\venv\lib\site-packages\django\shortcuts.py", line 25, in render
    content = loader.render_to_string(template_name, context, request, using=using)
  File "C:\Local Disk E\BlitzTech Systems\erpdev\venv\lib\site-packages\django\template\loader.py", line 62, in render_to_string
    return template.render(context, request)
  File "C:\Local Disk E\BlitzTech Systems\erpdev\venv\lib\site-packages\django\template\backends\django.py", line 107, in render
    return self.template.render(context)
  File "C:\Local Disk E\BlitzTech Systems\erpdev\venv\lib\site-packages\django\template\base.py", line 169, in render
    with context.bind_template(self):
  File "C:\Users\LENOVO\AppData\Local\Programs\Python\Python310\lib\contextlib.py", line 135, in __enter__
    return next(self.gen)
  File "C:\Local Disk E\BlitzTech Systems\erpdev\venv\lib\site-packages\django\template\context.py", line 253, in bind_template
    processors = template.engine.template_context_processors + self._processors
  File "C:\Local Disk E\BlitzTech Systems\erpdev\venv\lib\site-packages\django\utils\functional.py", line 47, in __get__
    res = instance.__dict__[self.name] = self.func(instance)
  File "C:\Local Disk E\BlitzTech Systems\erpdev\venv\lib\site-packages\django\template\engine.py", line 118, in template_context_processors
    return tuple(import_string(path) for path in context_processors)
  File "C:\Local Disk E\BlitzTech Systems\erpdev\venv\lib\site-packages\django\template\engine.py", line 118, in <genexpr>
    return tuple(import_string(path) for path in context_processors)
  File "C:\Local Disk E\BlitzTech Systems\erpdev\venv\lib\site-packages\django\utils\module_loading.py", line 32, in import_string
    raise ImportError(
ImportError: Module "core.context_processors" does not define a "site_settings" attribute/class
ERROR 2025-08-28 16:25:13,053 basehttp 46640 32640 "GET / HTTP/1.1" 500 170880
INFO 2025-08-28 16:25:59,528 autoreload 46640 44800 C:\Local Disk E\BlitzTech Systems\erpdev\blitzhub\settings.py changed, reloading.
INFO 2025-08-28 16:26:01,456 autoreload 37972 14184 Watching for file changes with StatReloader
ERROR 2025-08-28 16:26:05,664 log 37972 39288 Internal Server Error: /
Traceback (most recent call last):
  File "C:\Local Disk E\BlitzTech Systems\erpdev\venv\lib\site-packages\django\template\backends\django.py", line 107, in render
    return self.template.render(context)
  File "C:\Local Disk E\BlitzTech Systems\erpdev\venv\lib\site-packages\django\template\base.py", line 171, in render
    return self._render(context)
  File "C:\Local Disk E\BlitzTech Systems\erpdev\venv\lib\site-packages\django\template\base.py", line 163, in _render
    return self.nodelist.render(context)
  File "C:\Local Disk E\BlitzTech Systems\erpdev\venv\lib\site-packages\django\template\base.py", line 1008, in render
    return SafeString("".join([node.render_annotated(context) for node in self]))
  File "C:\Local Disk E\BlitzTech Systems\erpdev\venv\lib\site-packages\django\template\base.py", line 1008, in <listcomp>
    return SafeString("".join([node.render_annotated(context) for node in self]))
  File "C:\Local Disk E\BlitzTech Systems\erpdev\venv\lib\site-packages\django\template\base.py", line 969, in render_annotated
    return self.render(context)
  File "C:\Local Disk E\BlitzTech Systems\erpdev\venv\lib\site-packages\django\template\loader_tags.py", line 134, in render
    compiled_parent = self.get_parent(context)
  File "C:\Local Disk E\BlitzTech Systems\erpdev\venv\lib\site-packages\django\template\loader_tags.py", line 131, in get_parent
    return self.find_template(parent, context)
  File "C:\Local Disk E\BlitzTech Systems\erpdev\venv\lib\site-packages\django\template\loader_tags.py", line 109, in find_template
    template, origin = context.template.engine.find_template(
  File "C:\Local Disk E\BlitzTech Systems\erpdev\venv\lib\site-packages\django\template\engine.py", line 163, in find_template
    raise TemplateDoesNotExist(name, tried=tried)
django.template.exceptions.TemplateDoesNotExist: website_base.html

The above exception was the direct cause of the following exception:

Traceback (most recent call last):
  File "C:\Local Disk E\BlitzTech Systems\erpdev\venv\lib\site-packages\django\core\handlers\exception.py", line 55, in inner
    response = get_response(request)
  File "C:\Local Disk E\BlitzTech Systems\erpdev\venv\lib\site-packages\django\core\handlers\base.py", line 197, in _get_response
    response = wrapped_callback(request, *callback_args, **callback_kwargs)
  File "C:\Local Disk E\BlitzTech Systems\erpdev\website\views.py", line 59, in home
    return render(request, 'website/index.html', context)
  File "C:\Local Disk E\BlitzTech Systems\erpdev\venv\lib\site-packages\django\shortcuts.py", line 25, in render
    content = loader.render_to_string(template_name, context, request, using=using)
  File "C:\Local Disk E\BlitzTech Systems\erpdev\venv\lib\site-packages\django\template\loader.py", line 62, in render_to_string
    return template.render(context, request)
  File "C:\Local Disk E\BlitzTech Systems\erpdev\venv\lib\site-packages\django\template\backends\django.py", line 109, in render
    reraise(exc, self.backend)
  File "C:\Local Disk E\BlitzTech Systems\erpdev\venv\lib\site-packages\django\template\backends\django.py", line 130, in reraise
    raise new from exc
django.template.exceptions.TemplateDoesNotExist: website_base.html
ERROR 2025-08-28 16:26:05,673 basehttp 37972 39288 "GET / HTTP/1.1" 500 192751
ERROR 2025-08-28 16:27:51,112 log 37972 39288 Internal Server Error: /
Traceback (most recent call last):
  File "C:\Local Disk E\BlitzTech Systems\erpdev\venv\lib\site-packages\django\template\backends\django.py", line 107, in render
    return self.template.render(context)
  File "C:\Local Disk E\BlitzTech Systems\erpdev\venv\lib\site-packages\django\template\base.py", line 171, in render
    return self._render(context)
  File "C:\Local Disk E\BlitzTech Systems\erpdev\venv\lib\site-packages\django\template\base.py", line 163, in _render
    return self.nodelist.render(context)
  File "C:\Local Disk E\BlitzTech Systems\erpdev\venv\lib\site-packages\django\template\base.py", line 1008, in render
    return SafeString("".join([node.render_annotated(context) for node in self]))
  File "C:\Local Disk E\BlitzTech Systems\erpdev\venv\lib\site-packages\django\template\base.py", line 1008, in <listcomp>
    return SafeString("".join([node.render_annotated(context) for node in self]))
  File "C:\Local Disk E\BlitzTech Systems\erpdev\venv\lib\site-packages\django\template\base.py", line 969, in render_annotated
    return self.render(context)
  File "C:\Local Disk E\BlitzTech Systems\erpdev\venv\lib\site-packages\django\template\loader_tags.py", line 134, in render
    compiled_parent = self.get_parent(context)
  File "C:\Local Disk E\BlitzTech Systems\erpdev\venv\lib\site-packages\django\template\loader_tags.py", line 131, in get_parent
    return self.find_template(parent, context)
  File "C:\Local Disk E\BlitzTech Systems\erpdev\venv\lib\site-packages\django\template\loader_tags.py", line 109, in find_template
    template, origin = context.template.engine.find_template(
  File "C:\Local Disk E\BlitzTech Systems\erpdev\venv\lib\site-packages\django\template\engine.py", line 163, in find_template
    raise TemplateDoesNotExist(name, tried=tried)
django.template.exceptions.TemplateDoesNotExist: website_base.html

The above exception was the direct cause of the following exception:

Traceback (most recent call last):
  File "C:\Local Disk E\BlitzTech Systems\erpdev\venv\lib\site-packages\django\core\handlers\exception.py", line 55, in inner
    response = get_response(request)
  File "C:\Local Disk E\BlitzTech Systems\erpdev\venv\lib\site-packages\django\core\handlers\base.py", line 197, in _get_response
    response = wrapped_callback(request, *callback_args, **callback_kwargs)
  File "C:\Local Disk E\BlitzTech Systems\erpdev\website\views.py", line 59, in home
    return render(request, 'website/index.html', context)
  File "C:\Local Disk E\BlitzTech Systems\erpdev\venv\lib\site-packages\django\shortcuts.py", line 25, in render
    content = loader.render_to_string(template_name, context, request, using=using)
  File "C:\Local Disk E\BlitzTech Systems\erpdev\venv\lib\site-packages\django\template\loader.py", line 62, in render_to_string
    return template.render(context, request)
  File "C:\Local Disk E\BlitzTech Systems\erpdev\venv\lib\site-packages\django\template\backends\django.py", line 109, in render
    reraise(exc, self.backend)
  File "C:\Local Disk E\BlitzTech Systems\erpdev\venv\lib\site-packages\django\template\backends\django.py", line 130, in reraise
    raise new from exc
django.template.exceptions.TemplateDoesNotExist: website_base.html
ERROR 2025-08-28 16:27:51,115 basehttp 37972 39288 "GET / HTTP/1.1" 500 192751
ERROR 2025-08-28 16:27:52,959 log 37972 39288 Internal Server Error: /
Traceback (most recent call last):
  File "C:\Local Disk E\BlitzTech Systems\erpdev\venv\lib\site-packages\django\template\backends\django.py", line 107, in render
    return self.template.render(context)
  File "C:\Local Disk E\BlitzTech Systems\erpdev\venv\lib\site-packages\django\template\base.py", line 171, in render
    return self._render(context)
  File "C:\Local Disk E\BlitzTech Systems\erpdev\venv\lib\site-packages\django\template\base.py", line 163, in _render
    return self.nodelist.render(context)
  File "C:\Local Disk E\BlitzTech Systems\erpdev\venv\lib\site-packages\django\template\base.py", line 1008, in render
    return SafeString("".join([node.render_annotated(context) for node in self]))
  File "C:\Local Disk E\BlitzTech Systems\erpdev\venv\lib\site-packages\django\template\base.py", line 1008, in <listcomp>
    return SafeString("".join([node.render_annotated(context) for node in self]))
  File "C:\Local Disk E\BlitzTech Systems\erpdev\venv\lib\site-packages\django\template\base.py", line 969, in render_annotated
    return self.render(context)
  File "C:\Local Disk E\BlitzTech Systems\erpdev\venv\lib\site-packages\django\template\loader_tags.py", line 134, in render
    compiled_parent = self.get_parent(context)
  File "C:\Local Disk E\BlitzTech Systems\erpdev\venv\lib\site-packages\django\template\loader_tags.py", line 131, in get_parent
    return self.find_template(parent, context)
  File "C:\Local Disk E\BlitzTech Systems\erpdev\venv\lib\site-packages\django\template\loader_tags.py", line 109, in find_template
    template, origin = context.template.engine.find_template(
  File "C:\Local Disk E\BlitzTech Systems\erpdev\venv\lib\site-packages\django\template\engine.py", line 163, in find_template
    raise TemplateDoesNotExist(name, tried=tried)
django.template.exceptions.TemplateDoesNotExist: website_base.html

The above exception was the direct cause of the following exception:

Traceback (most recent call last):
  File "C:\Local Disk E\BlitzTech Systems\erpdev\venv\lib\site-packages\django\core\handlers\exception.py", line 55, in inner
    response = get_response(request)
  File "C:\Local Disk E\BlitzTech Systems\erpdev\venv\lib\site-packages\django\core\handlers\base.py", line 197, in _get_response
    response = wrapped_callback(request, *callback_args, **callback_kwargs)
  File "C:\Local Disk E\BlitzTech Systems\erpdev\website\views.py", line 59, in home
    return render(request, 'website/index.html', context)
  File "C:\Local Disk E\BlitzTech Systems\erpdev\venv\lib\site-packages\django\shortcuts.py", line 25, in render
    content = loader.render_to_string(template_name, context, request, using=using)
  File "C:\Local Disk E\BlitzTech Systems\erpdev\venv\lib\site-packages\django\template\loader.py", line 62, in render_to_string
    return template.render(context, request)
  File "C:\Local Disk E\BlitzTech Systems\erpdev\venv\lib\site-packages\django\template\backends\django.py", line 109, in render
    reraise(exc, self.backend)
  File "C:\Local Disk E\BlitzTech Systems\erpdev\venv\lib\site-packages\django\template\backends\django.py", line 130, in reraise
    raise new from exc
django.template.exceptions.TemplateDoesNotExist: website_base.html
ERROR 2025-08-28 16:27:52,963 basehttp 37972 39288 "GET / HTTP/1.1" 500 192751
ERROR 2025-08-28 16:27:53,937 log 37972 39288 Internal Server Error: /
Traceback (most recent call last):
  File "C:\Local Disk E\BlitzTech Systems\erpdev\venv\lib\site-packages\django\template\backends\django.py", line 107, in render
    return self.template.render(context)
  File "C:\Local Disk E\BlitzTech Systems\erpdev\venv\lib\site-packages\django\template\base.py", line 171, in render
    return self._render(context)
  File "C:\Local Disk E\BlitzTech Systems\erpdev\venv\lib\site-packages\django\template\base.py", line 163, in _render
    return self.nodelist.render(context)
  File "C:\Local Disk E\BlitzTech Systems\erpdev\venv\lib\site-packages\django\template\base.py", line 1008, in render
    return SafeString("".join([node.render_annotated(context) for node in self]))
  File "C:\Local Disk E\BlitzTech Systems\erpdev\venv\lib\site-packages\django\template\base.py", line 1008, in <listcomp>
    return SafeString("".join([node.render_annotated(context) for node in self]))
  File "C:\Local Disk E\BlitzTech Systems\erpdev\venv\lib\site-packages\django\template\base.py", line 969, in render_annotated
    return self.render(context)
  File "C:\Local Disk E\BlitzTech Systems\erpdev\venv\lib\site-packages\django\template\loader_tags.py", line 134, in render
    compiled_parent = self.get_parent(context)
  File "C:\Local Disk E\BlitzTech Systems\erpdev\venv\lib\site-packages\django\template\loader_tags.py", line 131, in get_parent
    return self.find_template(parent, context)
  File "C:\Local Disk E\BlitzTech Systems\erpdev\venv\lib\site-packages\django\template\loader_tags.py", line 109, in find_template
    template, origin = context.template.engine.find_template(
  File "C:\Local Disk E\BlitzTech Systems\erpdev\venv\lib\site-packages\django\template\engine.py", line 163, in find_template
    raise TemplateDoesNotExist(name, tried=tried)
django.template.exceptions.TemplateDoesNotExist: website_base.html

The above exception was the direct cause of the following exception:

Traceback (most recent call last):
  File "C:\Local Disk E\BlitzTech Systems\erpdev\venv\lib\site-packages\django\core\handlers\exception.py", line 55, in inner
    response = get_response(request)
  File "C:\Local Disk E\BlitzTech Systems\erpdev\venv\lib\site-packages\django\core\handlers\base.py", line 197, in _get_response
    response = wrapped_callback(request, *callback_args, **callback_kwargs)
  File "C:\Local Disk E\BlitzTech Systems\erpdev\website\views.py", line 59, in home
    return render(request, 'website/index.html', context)
  File "C:\Local Disk E\BlitzTech Systems\erpdev\venv\lib\site-packages\django\shortcuts.py", line 25, in render
    content = loader.render_to_string(template_name, context, request, using=using)
  File "C:\Local Disk E\BlitzTech Systems\erpdev\venv\lib\site-packages\django\template\loader.py", line 62, in render_to_string
    return template.render(context, request)
  File "C:\Local Disk E\BlitzTech Systems\erpdev\venv\lib\site-packages\django\template\backends\django.py", line 109, in render
    reraise(exc, self.backend)
  File "C:\Local Disk E\BlitzTech Systems\erpdev\venv\lib\site-packages\django\template\backends\django.py", line 130, in reraise
    raise new from exc
django.template.exceptions.TemplateDoesNotExist: website_base.html
ERROR 2025-08-28 16:27:53,941 basehttp 37972 39288 "GET / HTTP/1.1" 500 192751
INFO 2025-08-28 16:27:54,867 basehttp 37972 39288 "GET /auth/dashboard/ HTTP/1.1" 302 0
INFO 2025-08-28 16:27:55,010 basehttp 37972 39288 "GET /auth/login/?next=/auth/dashboard/ HTTP/1.1" 200 12774
INFO 2025-08-28 16:27:56,201 basehttp 37972 39288 "GET /auth/login/?next=/auth/dashboard/ HTTP/1.1" 200 12774
ERROR 2025-08-28 16:27:59,731 log 37972 39288 Internal Server Error: /quotes/
Traceback (most recent call last):
  File "C:\Local Disk E\BlitzTech Systems\erpdev\venv\lib\site-packages\django\db\models\fields\__init__.py", line 2123, in get_prep_value
    return int(value)
TypeError: int() argument must be a string, a bytes-like object or a real number, not 'SimpleLazyObject'

The above exception was the direct cause of the following exception:

Traceback (most recent call last):
  File "C:\Local Disk E\BlitzTech Systems\erpdev\venv\lib\site-packages\django\core\handlers\exception.py", line 55, in inner
    response = get_response(request)
  File "C:\Local Disk E\BlitzTech Systems\erpdev\venv\lib\site-packages\django\core\handlers\base.py", line 197, in _get_response
    response = wrapped_callback(request, *callback_args, **callback_kwargs)
  File "C:\Local Disk E\BlitzTech Systems\erpdev\core\decorators.py", line 520, in _wrapped_view
    return view_func(request, *args, **kwargs)
  File "C:\Local Disk E\BlitzTech Systems\erpdev\quotes\views.py", line 56, in quote_dashboard
    total_quotes = Quote.objects.filter(user_filter).count()
  File "C:\Local Disk E\BlitzTech Systems\erpdev\venv\lib\site-packages\django\db\models\manager.py", line 87, in manager_method
    return getattr(self.get_queryset(), name)(*args, **kwargs)
  File "C:\Local Disk E\BlitzTech Systems\erpdev\venv\lib\site-packages\django\db\models\query.py", line 1476, in filter
    return self._filter_or_exclude(False, args, kwargs)
  File "C:\Local Disk E\BlitzTech Systems\erpdev\venv\lib\site-packages\django\db\models\query.py", line 1494, in _filter_or_exclude
    clone._filter_or_exclude_inplace(negate, args, kwargs)
  File "C:\Local Disk E\BlitzTech Systems\erpdev\venv\lib\site-packages\django\db\models\query.py", line 1501, in _filter_or_exclude_inplace
    self._query.add_q(Q(*args, **kwargs))
  File "C:\Local Disk E\BlitzTech Systems\erpdev\venv\lib\site-packages\django\db\models\sql\query.py", line 1609, in add_q
    clause, _ = self._add_q(q_object, self.used_aliases)
  File "C:\Local Disk E\BlitzTech Systems\erpdev\venv\lib\site-packages\django\db\models\sql\query.py", line 1641, in _add_q
    child_clause, needed_inner = self.build_filter(
  File "C:\Local Disk E\BlitzTech Systems\erpdev\venv\lib\site-packages\django\db\models\sql\query.py", line 1468, in build_filter
    return self._add_q(
  File "C:\Local Disk E\BlitzTech Systems\erpdev\venv\lib\site-packages\django\db\models\sql\query.py", line 1641, in _add_q
    child_clause, needed_inner = self.build_filter(
  File "C:\Local Disk E\BlitzTech Systems\erpdev\venv\lib\site-packages\django\db\models\sql\query.py", line 1555, in build_filter
    condition = self.build_lookup(lookups, col, value)
  File "C:\Local Disk E\BlitzTech Systems\erpdev\venv\lib\site-packages\django\db\models\sql\query.py", line 1385, in build_lookup
    lookup = lookup_class(lhs, rhs)
  File "C:\Local Disk E\BlitzTech Systems\erpdev\venv\lib\site-packages\django\db\models\lookups.py", line 30, in __init__
    self.rhs = self.get_prep_lookup()
  File "C:\Local Disk E\BlitzTech Systems\erpdev\venv\lib\site-packages\django\db\models\fields\related_lookups.py", line 156, in get_prep_lookup
    self.rhs = target_field.get_prep_value(self.rhs)
  File "C:\Local Disk E\BlitzTech Systems\erpdev\venv\lib\site-packages\django\db\models\fields\__init__.py", line 2125, in get_prep_value
    raise e.__class__(
TypeError: Field 'id' expected a number but got <SimpleLazyObject: <django.contrib.auth.models.AnonymousUser object at 0x00000246B8B19F60>>.
ERROR 2025-08-28 16:27:59,737 basehttp 37972 39288 "GET /quotes/ HTTP/1.1" 500 184439
ERROR 2025-08-28 16:28:01,078 log 37972 39288 Internal Server Error: /crm/
Traceback (most recent call last):
  File "C:\Local Disk E\BlitzTech Systems\erpdev\venv\lib\site-packages\django\db\models\fields\__init__.py", line 2123, in get_prep_value
    return int(value)
TypeError: int() argument must be a string, a bytes-like object or a real number, not 'SimpleLazyObject'

The above exception was the direct cause of the following exception:

Traceback (most recent call last):
  File "C:\Local Disk E\BlitzTech Systems\erpdev\venv\lib\site-packages\django\core\handlers\exception.py", line 55, in inner
    response = get_response(request)
  File "C:\Local Disk E\BlitzTech Systems\erpdev\venv\lib\site-packages\django\core\handlers\base.py", line 197, in _get_response
    response = wrapped_callback(request, *callback_args, **callback_kwargs)
  File "C:\Local Disk E\BlitzTech Systems\erpdev\core\decorators.py", line 520, in _wrapped_view
    return view_func(request, *args, **kwargs)
  File "C:\Local Disk E\BlitzTech Systems\erpdev\crm\views.py", line 87, in crm_dashboard
    'overdue_count': Task.objects.filter(
  File "C:\Local Disk E\BlitzTech Systems\erpdev\venv\lib\site-packages\django\db\models\manager.py", line 87, in manager_method
    return getattr(self.get_queryset(), name)(*args, **kwargs)
  File "C:\Local Disk E\BlitzTech Systems\erpdev\venv\lib\site-packages\django\db\models\query.py", line 1476, in filter
    return self._filter_or_exclude(False, args, kwargs)
  File "C:\Local Disk E\BlitzTech Systems\erpdev\venv\lib\site-packages\django\db\models\query.py", line 1494, in _filter_or_exclude
    clone._filter_or_exclude_inplace(negate, args, kwargs)
  File "C:\Local Disk E\BlitzTech Systems\erpdev\venv\lib\site-packages\django\db\models\query.py", line 1501, in _filter_or_exclude_inplace
    self._query.add_q(Q(*args, **kwargs))
  File "C:\Local Disk E\BlitzTech Systems\erpdev\venv\lib\site-packages\django\db\models\sql\query.py", line 1609, in add_q
    clause, _ = self._add_q(q_object, self.used_aliases)
  File "C:\Local Disk E\BlitzTech Systems\erpdev\venv\lib\site-packages\django\db\models\sql\query.py", line 1641, in _add_q
    child_clause, needed_inner = self.build_filter(
  File "C:\Local Disk E\BlitzTech Systems\erpdev\venv\lib\site-packages\django\db\models\sql\query.py", line 1555, in build_filter
    condition = self.build_lookup(lookups, col, value)
  File "C:\Local Disk E\BlitzTech Systems\erpdev\venv\lib\site-packages\django\db\models\sql\query.py", line 1385, in build_lookup
    lookup = lookup_class(lhs, rhs)
  File "C:\Local Disk E\BlitzTech Systems\erpdev\venv\lib\site-packages\django\db\models\lookups.py", line 30, in __init__
    self.rhs = self.get_prep_lookup()
  File "C:\Local Disk E\BlitzTech Systems\erpdev\venv\lib\site-packages\django\db\models\fields\related_lookups.py", line 156, in get_prep_lookup
    self.rhs = target_field.get_prep_value(self.rhs)
  File "C:\Local Disk E\BlitzTech Systems\erpdev\venv\lib\site-packages\django\db\models\fields\__init__.py", line 2125, in get_prep_value
    raise e.__class__(
TypeError: Field 'id' expected a number but got <SimpleLazyObject: <django.contrib.auth.models.AnonymousUser object at 0x00000246B8A3D630>>.
ERROR 2025-08-28 16:28:01,083 basehttp 37972 39288 "GET /crm/ HTTP/1.1" 500 174421
INFO 2025-08-28 16:28:02,067 basehttp 37972 39288 "GET /auth/login/?next=/auth/dashboard/ HTTP/1.1" 200 12774
INFO 2025-08-28 16:28:04,009 basehttp 37972 39288 "GET /auth/login/?next=/auth/dashboard/ HTTP/1.1" 200 12774
INFO 2025-08-28 16:28:07,860 basehttp 37972 39288 "POST /auth/login/?next=/auth/dashboard/ HTTP/1.1" 302 0
INFO 2025-08-28 16:28:08,174 basehttp 37972 39288 "GET /auth/dashboard/ HTTP/1.1" 200 54054
INFO 2025-08-28 16:28:15,728 basehttp 37972 39288 "GET /auth/logout/ HTTP/1.1" 302 0
ERROR 2025-08-28 16:28:16,098 log 37972 39288 Internal Server Error: /
Traceback (most recent call last):
  File "C:\Local Disk E\BlitzTech Systems\erpdev\venv\lib\site-packages\django\template\backends\django.py", line 107, in render
    return self.template.render(context)
  File "C:\Local Disk E\BlitzTech Systems\erpdev\venv\lib\site-packages\django\template\base.py", line 171, in render
    return self._render(context)
  File "C:\Local Disk E\BlitzTech Systems\erpdev\venv\lib\site-packages\django\template\base.py", line 163, in _render
    return self.nodelist.render(context)
  File "C:\Local Disk E\BlitzTech Systems\erpdev\venv\lib\site-packages\django\template\base.py", line 1008, in render
    return SafeString("".join([node.render_annotated(context) for node in self]))
  File "C:\Local Disk E\BlitzTech Systems\erpdev\venv\lib\site-packages\django\template\base.py", line 1008, in <listcomp>
    return SafeString("".join([node.render_annotated(context) for node in self]))
  File "C:\Local Disk E\BlitzTech Systems\erpdev\venv\lib\site-packages\django\template\base.py", line 969, in render_annotated
    return self.render(context)
  File "C:\Local Disk E\BlitzTech Systems\erpdev\venv\lib\site-packages\django\template\loader_tags.py", line 134, in render
    compiled_parent = self.get_parent(context)
  File "C:\Local Disk E\BlitzTech Systems\erpdev\venv\lib\site-packages\django\template\loader_tags.py", line 131, in get_parent
    return self.find_template(parent, context)
  File "C:\Local Disk E\BlitzTech Systems\erpdev\venv\lib\site-packages\django\template\loader_tags.py", line 109, in find_template
    template, origin = context.template.engine.find_template(
  File "C:\Local Disk E\BlitzTech Systems\erpdev\venv\lib\site-packages\django\template\engine.py", line 163, in find_template
    raise TemplateDoesNotExist(name, tried=tried)
django.template.exceptions.TemplateDoesNotExist: website_base.html

The above exception was the direct cause of the following exception:

Traceback (most recent call last):
  File "C:\Local Disk E\BlitzTech Systems\erpdev\venv\lib\site-packages\django\core\handlers\exception.py", line 55, in inner
    response = get_response(request)
  File "C:\Local Disk E\BlitzTech Systems\erpdev\venv\lib\site-packages\django\core\handlers\base.py", line 197, in _get_response
    response = wrapped_callback(request, *callback_args, **callback_kwargs)
  File "C:\Local Disk E\BlitzTech Systems\erpdev\website\views.py", line 59, in home
    return render(request, 'website/index.html', context)
  File "C:\Local Disk E\BlitzTech Systems\erpdev\venv\lib\site-packages\django\shortcuts.py", line 25, in render
    content = loader.render_to_string(template_name, context, request, using=using)
  File "C:\Local Disk E\BlitzTech Systems\erpdev\venv\lib\site-packages\django\template\loader.py", line 62, in render_to_string
    return template.render(context, request)
  File "C:\Local Disk E\BlitzTech Systems\erpdev\venv\lib\site-packages\django\template\backends\django.py", line 109, in render
    reraise(exc, self.backend)
  File "C:\Local Disk E\BlitzTech Systems\erpdev\venv\lib\site-packages\django\template\backends\django.py", line 130, in reraise
    raise new from exc
django.template.exceptions.TemplateDoesNotExist: website_base.html
ERROR 2025-08-28 16:28:16,102 basehttp 37972 39288 "GET / HTTP/1.1" 500 192885
INFO 2025-08-28 16:29:02,706 autoreload 31516 28616 Watching for file changes with StatReloader
INFO 2025-08-28 16:29:07,353 basehttp 31516 34204 "GET / HTTP/1.1" 200 34474
WARNING 2025-08-28 16:29:07,519 basehttp 31516 34204 "GET /static/website/img/portfolio-1.jpg HTTP/1.1" 404 2008
WARNING 2025-08-28 16:29:07,532 basehttp 31516 5096 "GET /static/website/img/client-3.jpg HTTP/1.1" 404 1999
WARNING 2025-08-28 16:29:07,533 basehttp 31516 42304 "GET /static/website/img/portfolio-3.jpg HTTP/1.1" 404 2008
WARNING 2025-08-28 16:29:07,533 basehttp 31516 19808 "GET /static/website/img/portfolio-2.jpg HTTP/1.1" 404 2008
WARNING 2025-08-28 16:29:07,534 basehttp 31516 41524 "GET /static/website/img/client-1.jpg HTTP/1.1" 404 1999
WARNING 2025-08-28 16:29:07,535 basehttp 31516 19236 "GET /static/website/img/client-2.jpg HTTP/1.1" 404 1999
WARNING 2025-08-28 16:29:07,582 basehttp 31516 38996 "GET /static/website/img/partner-2.png HTTP/1.1" 404 2002
WARNING 2025-08-28 16:29:07,583 basehttp 31516 5632 "GET /static/website/img/partner-4.png HTTP/1.1" 404 2002
WARNING 2025-08-28 16:29:07,583 basehttp 31516 15396 "GET /static/website/img/partner-3.png HTTP/1.1" 404 2002
WARNING 2025-08-28 16:29:07,600 basehttp 31516 43316 "GET /static/website/img/partner-5.png HTTP/1.1" 404 2002
WARNING 2025-08-28 16:29:07,601 basehttp 31516 33972 "GET /static/website/img/partner-6.png HTTP/1.1" 404 2002
WARNING 2025-08-28 16:29:07,602 basehttp 31516 19272 "GET /static/website/img/partner-1.png HTTP/1.1" 404 2002
INFO 2025-08-28 16:29:09,457 basehttp 31516 33172 "GET / HTTP/1.1" 200 34067
WARNING 2025-08-28 16:29:09,484 basehttp 31516 33172 "GET /static/website/img/portfolio-1.jpg HTTP/1.1" 404 2008
WARNING 2025-08-28 16:29:09,505 basehttp 31516 46452 "GET /static/website/img/portfolio-3.jpg HTTP/1.1" 404 2008
WARNING 2025-08-28 16:29:09,524 basehttp 31516 43568 "GET /static/website/img/client-3.jpg HTTP/1.1" 404 1999
WARNING 2025-08-28 16:29:09,543 basehttp 31516 36136 "GET /static/website/img/portfolio-2.jpg HTTP/1.1" 404 2008
WARNING 2025-08-28 16:29:09,544 basehttp 31516 3292 "GET /static/website/img/client-2.jpg HTTP/1.1" 404 1999
WARNING 2025-08-28 16:29:09,545 basehttp 31516 46372 "GET /static/website/img/client-1.jpg HTTP/1.1" 404 1999
WARNING 2025-08-28 16:29:09,559 basehttp 31516 33348 "GET /static/website/img/partner-1.png HTTP/1.1" 404 2002
WARNING 2025-08-28 16:29:09,573 basehttp 31516 40596 "GET /static/website/img/partner-2.png HTTP/1.1" 404 2002
WARNING 2025-08-28 16:29:09,587 basehttp 31516 39780 "GET /static/website/img/partner-3.png HTTP/1.1" 404 2002
WARNING 2025-08-28 16:29:09,587 basehttp 31516 21108 "GET /static/website/img/partner-5.png HTTP/1.1" 404 2002
WARNING 2025-08-28 16:29:09,604 basehttp 31516 27796 "GET /static/website/img/partner-4.png HTTP/1.1" 404 2002
WARNING 2025-08-28 16:29:09,604 basehttp 31516 46936 "GET /static/website/img/partner-6.png HTTP/1.1" 404 2002
INFO 2025-08-28 16:29:15,646 basehttp 31516 4692 "GET /auth/login/?type=employee HTTP/1.1" 200 12775
INFO 2025-08-28 16:29:19,563 basehttp 31516 4692 "POST /auth/login/?type=employee HTTP/1.1" 302 0
INFO 2025-08-28 16:29:20,302 basehttp 31516 4692 "GET /auth/dashboard/ HTTP/1.1" 200 54054
INFO 2025-08-28 16:29:32,480 basehttp 31516 4692 "GET /admin-dashboard/ HTTP/1.1" 200 49274
INFO 2025-08-28 16:29:54,198 basehttp 31516 4692 "GET /auth/dashboard/ HTTP/1.1" 200 53290
INFO 2025-08-28 16:29:56,493 basehttp 31516 4692 "GET /crm/ HTTP/1.1" 200 48213
INFO 2025-08-28 16:29:58,890 basehttp 31516 4692 "GET /quotes/ HTTP/1.1" 200 36018
INFO 2025-08-28 16:30:01,965 basehttp 31516 4692 "GET /crm/ HTTP/1.1" 200 48213
INFO 2025-08-28 16:30:02,716 basehttp 31516 4692 "GET /quotes/ HTTP/1.1" 200 36018
INFO 2025-08-28 16:30:05,252 basehttp 31516 4692 "GET /quotes/ HTTP/1.1" 200 36018
INFO 2025-08-28 16:30:06,356 basehttp 31516 4692 "GET /admin-dashboard/ HTTP/1.1" 200 49274
INFO 2025-08-28 16:30:08,766 basehttp 31516 4692 "GET /auth/employees/ HTTP/1.1" 200 206649
INFO 2025-08-28 16:30:17,223 basehttp 31516 4692 "GET /auth/system-settings/ HTTP/1.1" 200 36956
WARNING 2025-08-28 16:33:25,170 log 31516 4692 Bad Request: /auth/api/get-notification-count/
WARNING 2025-08-28 16:33:25,176 basehttp 31516 4692 "GET /auth/api/get-notification-count/ HTTP/1.1" 400 34
INFO 2025-08-28 16:33:28,429 basehttp 31516 4692 "GET /auth/system-reports/ HTTP/1.1" 200 36083
INFO 2025-08-28 16:33:30,699 basehttp 31516 4692 "GET /auth/users/ HTTP/1.1" 200 142394
INFO 2025-08-28 16:33:38,660 basehttp 31516 4692 "GET /admin-dashboard/ HTTP/1.1" 200 49274
ERROR 2025-08-28 16:33:42,764 log 31516 4692 Internal Server Error: /inventory/
Traceback (most recent call last):
  File "C:\Local Disk E\BlitzTech Systems\erpdev\venv\lib\site-packages\django\db\backends\utils.py", line 105, in _execute
    return self.cursor.execute(sql, params)
psycopg2.errors.UndefinedTable: relation "inventory_brand" does not exist
LINE 1: SELECT COUNT(*) AS "__count" FROM "inventory_brand" WHERE "i...
                                          ^


The above exception was the direct cause of the following exception:

Traceback (most recent call last):
  File "C:\Local Disk E\BlitzTech Systems\erpdev\venv\lib\site-packages\django\core\handlers\exception.py", line 55, in inner
    response = get_response(request)
  File "C:\Local Disk E\BlitzTech Systems\erpdev\venv\lib\site-packages\django\core\handlers\base.py", line 197, in _get_response
    response = wrapped_callback(request, *callback_args, **callback_kwargs)
  File "C:\Local Disk E\BlitzTech Systems\erpdev\venv\lib\site-packages\django\views\generic\base.py", line 104, in view
    return self.dispatch(request, *args, **kwargs)
  File "C:\Local Disk E\BlitzTech Systems\erpdev\venv\lib\site-packages\django\utils\decorators.py", line 48, in _wrapper
    return bound_method(*args, **kwargs)
  File "C:\Local Disk E\BlitzTech Systems\erpdev\venv\lib\site-packages\django\contrib\auth\decorators.py", line 60, in _view_wrapper
    return view_func(request, *args, **kwargs)
  File "C:\Local Disk E\BlitzTech Systems\erpdev\inventory\decorators.py", line 75, in _wrapped_view
    return view_func(request, *args, **kwargs)
  File "C:\Local Disk E\BlitzTech Systems\erpdev\inventory\views.py", line 89, in dispatch
    return super().dispatch(*args, **kwargs)
  File "C:\Local Disk E\BlitzTech Systems\erpdev\venv\lib\site-packages\django\contrib\auth\mixins.py", line 73, in dispatch
    return super().dispatch(request, *args, **kwargs)
  File "C:\Local Disk E\BlitzTech Systems\erpdev\venv\lib\site-packages\django\views\generic\base.py", line 143, in dispatch
    return handler(request, *args, **kwargs)
  File "C:\Local Disk E\BlitzTech Systems\erpdev\venv\lib\site-packages\django\views\generic\base.py", line 226, in get
    context = self.get_context_data(**kwargs)
  File "C:\Local Disk E\BlitzTech Systems\erpdev\inventory\views.py", line 100, in get_context_data
    'total_brands': Brand.objects.filter(is_active=True).count(),
  File "C:\Local Disk E\BlitzTech Systems\erpdev\venv\lib\site-packages\django\db\models\query.py", line 620, in count
    return self.query.get_count(using=self.db)
  File "C:\Local Disk E\BlitzTech Systems\erpdev\venv\lib\site-packages\django\db\models\sql\query.py", line 630, in get_count
    return obj.get_aggregation(using, {"__count": Count("*")})["__count"]
  File "C:\Local Disk E\BlitzTech Systems\erpdev\venv\lib\site-packages\django\db\models\sql\query.py", line 616, in get_aggregation
    result = compiler.execute_sql(SINGLE)
  File "C:\Local Disk E\BlitzTech Systems\erpdev\venv\lib\site-packages\django\db\models\sql\compiler.py", line 1574, in execute_sql
    cursor.execute(sql, params)
  File "C:\Local Disk E\BlitzTech Systems\erpdev\venv\lib\site-packages\django\db\backends\utils.py", line 122, in execute
    return super().execute(sql, params)
  File "C:\Local Disk E\BlitzTech Systems\erpdev\venv\lib\site-packages\django\db\backends\utils.py", line 79, in execute
    return self._execute_with_wrappers(
  File "C:\Local Disk E\BlitzTech Systems\erpdev\venv\lib\site-packages\django\db\backends\utils.py", line 92, in _execute_with_wrappers
    return executor(sql, params, many, context)
  File "C:\Local Disk E\BlitzTech Systems\erpdev\venv\lib\site-packages\django\db\backends\utils.py", line 100, in _execute
    with self.db.wrap_database_errors:
  File "C:\Local Disk E\BlitzTech Systems\erpdev\venv\lib\site-packages\django\db\utils.py", line 91, in __exit__
    raise dj_exc_value.with_traceback(traceback) from exc_value
  File "C:\Local Disk E\BlitzTech Systems\erpdev\venv\lib\site-packages\django\db\backends\utils.py", line 105, in _execute
    return self.cursor.execute(sql, params)
django.db.utils.ProgrammingError: relation "inventory_brand" does not exist
LINE 1: SELECT COUNT(*) AS "__count" FROM "inventory_brand" WHERE "i...
                                          ^

ERROR 2025-08-28 16:33:42,793 basehttp 31516 4692 "GET /inventory/ HTTP/1.1" 500 200366
WARNING 2025-08-28 16:33:46,189 log 31516 4692 Bad Request: /auth/api/get-notification-count/
WARNING 2025-08-28 16:33:46,194 basehttp 31516 4692 "GET /auth/api/get-notification-count/ HTTP/1.1" 400 34
WARNING 2025-08-28 16:33:46,359 log 31516 36868 Bad Request: /auth/api/get-notification-count/
WARNING 2025-08-28 16:33:46,361 basehttp 31516 36868 "GET /auth/api/get-notification-count/ HTTP/1.1" 400 34
INFO 2025-08-28 16:52:30,912 autoreload 24160 47088 Watching for file changes with StatReloader
INFO 2025-08-28 16:52:42,613 basehttp 24160 42496 "GET /inventory/ HTTP/1.1" 302 0
INFO 2025-08-28 16:52:42,835 basehttp 24160 42496 "GET /auth/login/?next=/inventory/ HTTP/1.1" 200 12774
INFO 2025-08-28 16:52:46,449 basehttp 24160 42496 "POST /auth/login/?next=/inventory/ HTTP/1.1" 200 12982
INFO 2025-08-28 16:54:09,352 signals 7540 36064 Created profile for user: posodraxy07
INFO 2025-08-28 16:54:55,659 signals 37548 42768 Created profile for user: poso.draxy@gmail.com
INFO 2025-08-28 16:55:04,318 autoreload 2288 21300 Watching for file changes with StatReloader
INFO 2025-08-28 16:55:13,902 basehttp 2288 35384 "GET / HTTP/1.1" 200 34067
INFO 2025-08-28 16:55:18,772 basehttp 2288 35384 "GET /static/website/img/blitztech-logo.png HTTP/1.1" 200 9495
INFO 2025-08-28 16:55:18,784 basehttp 2288 35384 "GET /static/website/img/about-image.jpg HTTP/1.1" 200 54795
INFO 2025-08-28 16:55:18,790 basehttp 2288 5736 "GET /static/website/img/hero-illustration.svg HTTP/1.1" 200 306187
INFO 2025-08-28 16:55:18,798 basehttp 2288 35384 "GET /static/website/img/drone-technology.jpg HTTP/1.1" 200 13030
INFO 2025-08-28 16:55:18,800 basehttp 2288 5736 "GET /static/website/img/iot-systems.jpg HTTP/1.1" 200 15906
WARNING 2025-08-28 16:55:18,870 basehttp 2288 35384 "GET /static/website/img/portfolio-2.jpg HTTP/1.1" 404 2008
WARNING 2025-08-28 16:55:18,873 basehttp 2288 5736 "GET /static/website/img/portfolio-1.jpg HTTP/1.1" 404 2008
WARNING 2025-08-28 16:55:18,891 basehttp 2288 46992 "GET /static/website/img/portfolio-3.jpg HTTP/1.1" 404 2008
WARNING 2025-08-28 16:55:18,943 basehttp 2288 38192 "GET /static/website/img/client-1.jpg HTTP/1.1" 404 1999
WARNING 2025-08-28 16:55:18,944 basehttp 2288 31916 "GET /static/website/img/client-2.jpg HTTP/1.1" 404 1999
INFO 2025-08-28 16:55:18,994 basehttp 2288 19636 "GET /static/website/img/hero-bg.jpg HTTP/1.1" 200 160322
WARNING 2025-08-28 16:55:19,383 basehttp 2288 19636 "GET /static/website/img/client-3.jpg HTTP/1.1" 404 1999
WARNING 2025-08-28 16:55:19,977 basehttp 2288 14080 "GET /static/website/img/partner-1.png HTTP/1.1" 404 2002
WARNING 2025-08-28 16:55:19,978 basehttp 2288 34272 "GET /static/website/img/partner-2.png HTTP/1.1" 404 2002
WARNING 2025-08-28 16:55:20,006 basehttp 2288 18196 "GET /static/website/img/partner-3.png HTTP/1.1" 404 2002
WARNING 2025-08-28 16:55:20,022 basehttp 2288 38176 "GET /static/website/img/partner-4.png HTTP/1.1" 404 2002
WARNING 2025-08-28 16:55:20,068 basehttp 2288 38448 "GET /static/website/img/partner-5.png HTTP/1.1" 404 2002
WARNING 2025-08-28 16:55:20,069 basehttp 2288 45980 "GET /static/website/img/partner-6.png HTTP/1.1" 404 2002
INFO 2025-08-28 16:55:23,388 basehttp 2288 45128 "GET /auth/login/?type=employee HTTP/1.1" 200 12775
INFO 2025-08-28 16:55:28,035 basehttp 2288 45128 "POST /auth/login/?type=employee HTTP/1.1" 302 0
INFO 2025-08-28 16:55:28,226 basehttp 2288 45128 "GET / HTTP/1.1" 200 34321
WARNING 2025-08-28 16:55:28,309 basehttp 2288 45128 "GET /static/website/img/portfolio-1.jpg HTTP/1.1" 404 2008
WARNING 2025-08-28 16:55:28,372 basehttp 2288 32148 "GET /static/website/img/portfolio-3.jpg HTTP/1.1" 404 2008
WARNING 2025-08-28 16:55:28,392 basehttp 2288 2612 "GET /static/website/img/client-1.jpg HTTP/1.1" 404 1999
WARNING 2025-08-28 16:55:28,394 basehttp 2288 19396 "GET /static/website/img/portfolio-2.jpg HTTP/1.1" 404 2008
WARNING 2025-08-28 16:55:28,396 basehttp 2288 28532 "GET /static/website/img/client-3.jpg HTTP/1.1" 404 1999
WARNING 2025-08-28 16:55:28,396 basehttp 2288 28012 "GET /static/website/img/client-2.jpg HTTP/1.1" 404 1999
WARNING 2025-08-28 16:55:28,428 basehttp 2288 19808 "GET /static/website/img/partner-1.png HTTP/1.1" 404 2002
WARNING 2025-08-28 16:55:28,454 basehttp 2288 21152 "GET /static/website/img/partner-2.png HTTP/1.1" 404 2002
WARNING 2025-08-28 16:55:28,473 basehttp 2288 42284 "GET /static/website/img/partner-3.png HTTP/1.1" 404 2002
WARNING 2025-08-28 16:55:28,507 basehttp 2288 46288 "GET /static/website/img/partner-4.png HTTP/1.1" 404 2002
WARNING 2025-08-28 16:55:28,511 basehttp 2288 46164 "GET /static/website/img/partner-5.png HTTP/1.1" 404 2002
WARNING 2025-08-28 16:55:28,524 basehttp 2288 30508 "GET /static/website/img/partner-6.png HTTP/1.1" 404 2002
INFO 2025-08-28 16:55:45,327 basehttp 2288 2200 "GET /admin/ HTTP/1.1" 200 39978
INFO 2025-08-28 16:55:45,391 basehttp 2288 2200 "GET /static/admin/css/base.css HTTP/1.1" 200 22092
INFO 2025-08-28 16:55:45,392 basehttp 2288 45576 "GET /static/admin/css/dashboard.css HTTP/1.1" 200 441
INFO 2025-08-28 16:55:45,393 basehttp 2288 45248 "GET /static/admin/css/dark_mode.css HTTP/1.1" 200 2804
INFO 2025-08-28 16:55:45,399 basehttp 2288 11864 "GET /static/admin/css/nav_sidebar.css HTTP/1.1" 200 2810
INFO 2025-08-28 16:55:45,409 basehttp 2288 32580 "GET /static/admin/css/responsive.css HTTP/1.1" 200 17972
INFO 2025-08-28 16:55:45,416 basehttp 2288 4388 "GET /static/admin/js/theme.js HTTP/1.1" 200 1653
INFO 2025-08-28 16:55:45,420 basehttp 2288 32580 "GET /static/admin/js/nav_sidebar.js HTTP/1.1" 200 3063
INFO 2025-08-28 16:55:45,442 basehttp 2288 11864 "GET /static/admin/img/icon-viewlink.svg HTTP/1.1" 200 581
INFO 2025-08-28 16:55:45,443 basehttp 2288 4388 "GET /static/admin/img/icon-changelink.svg HTTP/1.1" 200 380
INFO 2025-08-28 16:55:45,444 basehttp 2288 32580 "GET /static/admin/img/icon-addlink.svg HTTP/1.1" 200 331
INFO 2025-08-28 16:55:47,619 basehttp 2288 32580 "GET /admin/auth/user/ HTTP/1.1" 200 39868
INFO 2025-08-28 16:55:47,682 basehttp 2288 32580 "GET /static/admin/css/changelists.css HTTP/1.1" 200 6878
INFO 2025-08-28 16:55:47,688 basehttp 2288 2200 "GET /static/admin/js/admin/RelatedObjectLookups.js HTTP/1.1" 200 9097
INFO 2025-08-28 16:55:47,689 basehttp 2288 45248 "GET /static/admin/js/jquery.init.js HTTP/1.1" 200 347
INFO 2025-08-28 16:55:47,690 basehttp 2288 45576 "GET /static/admin/js/core.js HTTP/1.1" 200 6208
INFO 2025-08-28 16:55:47,704 basehttp 2288 32580 "GET /static/admin/js/actions.js HTTP/1.1" 200 8076
INFO 2025-08-28 16:55:47,712 basehttp 2288 45248 "GET /static/admin/js/urlify.js HTTP/1.1" 200 7887
INFO 2025-08-28 16:55:47,714 basehttp 2288 2200 "GET /static/admin/js/prepopulate.js HTTP/1.1" 200 1531
INFO 2025-08-28 16:55:47,725 basehttp 2288 11864 "GET /static/admin/js/vendor/jquery/jquery.js HTTP/1.1" 200 285314
INFO 2025-08-28 16:55:47,741 basehttp 2288 2200 "GET /static/admin/img/icon-yes.svg HTTP/1.1" 200 436
INFO 2025-08-28 16:55:47,743 basehttp 2288 11864 "GET /static/admin/img/search.svg HTTP/1.1" 200 458
INFO 2025-08-28 16:55:47,748 basehttp 2288 45576 "GET /static/admin/js/vendor/xregexp/xregexp.js HTTP/1.1" 200 325171
INFO 2025-08-28 16:55:47,761 basehttp 2288 45576 "GET /static/admin/js/filters.js HTTP/1.1" 200 978
INFO 2025-08-28 16:55:47,812 basehttp 2288 4388 "GET /admin/jsi18n/ HTTP/1.1" 200 3342
INFO 2025-08-28 16:55:47,856 basehttp 2288 4388 "GET /static/admin/img/tooltag-add.svg HTTP/1.1" 200 331
INFO 2025-08-28 16:55:47,865 basehttp 2288 45576 "GET /static/admin/img/sorting-icons.svg HTTP/1.1" 200 1097
INFO 2025-08-28 16:55:50,519 basehttp 2288 45576 "GET /admin/auth/user/1/change/ HTTP/1.1" 200 75322
INFO 2025-08-28 16:55:50,564 basehttp 2288 45576 "GET /static/admin/css/forms.css HTTP/1.1" 200 8794
INFO 2025-08-28 16:55:50,575 basehttp 2288 11864 "GET /static/admin/js/calendar.js HTTP/1.1" 200 9141
INFO 2025-08-28 16:55:50,577 basehttp 2288 32580 "GET /static/admin/js/SelectBox.js HTTP/1.1" 200 4530
INFO 2025-08-28 16:55:50,582 basehttp 2288 45248 "GET /static/admin/js/inlines.js HTTP/1.1" 200 15526
INFO 2025-08-28 16:55:50,582 basehttp 2288 2200 "GET /static/admin/js/admin/DateTimeShortcuts.js HTTP/1.1" 200 19319
INFO 2025-08-28 16:55:50,587 basehttp 2288 45576 "GET /static/admin/js/SelectFilter2.js HTTP/1.1" 200 15502
INFO 2025-08-28 16:55:50,589 basehttp 2288 11864 "GET /static/admin/css/widgets.css HTTP/1.1" 200 11564
INFO 2025-08-28 16:55:50,599 basehttp 2288 45576 "GET /static/admin/js/prepopulate_init.js HTTP/1.1" 200 586
INFO 2025-08-28 16:55:50,608 basehttp 2288 45576 "GET /static/admin/img/icon-unknown.svg HTTP/1.1" 200 655
INFO 2025-08-28 16:55:50,619 basehttp 2288 45576 "GET /static/admin/js/change_form.js HTTP/1.1" 200 606
INFO 2025-08-28 16:55:50,708 basehttp 2288 4388 "GET /admin/jsi18n/ HTTP/1.1" 200 3342
INFO 2025-08-28 16:55:50,818 basehttp 2288 4388 "GET /static/admin/img/selector-icons.svg HTTP/1.1" 200 3291
INFO 2025-08-28 16:55:50,819 basehttp 2288 11864 "GET /static/admin/img/icon-calendar.svg HTTP/1.1" 200 1086
INFO 2025-08-28 16:55:50,820 basehttp 2288 2200 "GET /static/admin/img/icon-clock.svg HTTP/1.1" 200 677
INFO 2025-08-28 16:55:50,821 basehttp 2288 45576 "GET /static/admin/img/icon-unknown-alt.svg HTTP/1.1" 200 655
INFO 2025-08-28 16:56:09,130 basehttp 2288 45576 "GET /static/admin/img/inline-delete.svg HTTP/1.1" 200 560
INFO 2025-08-28 16:56:19,803 basehttp 2288 45576 "POST /admin/auth/user/1/change/ HTTP/1.1" 302 0
INFO 2025-08-28 16:56:20,119 basehttp 2288 45576 "GET /admin/auth/user/ HTTP/1.1" 200 40076
INFO 2025-08-28 16:56:20,299 basehttp 2288 45576 "GET /admin/jsi18n/ HTTP/1.1" 200 3342
INFO 2025-08-28 16:56:25,483 basehttp 2288 45576 "GET /admin/auth/user/2/change/ HTTP/1.1" 200 75331
INFO 2025-08-28 16:56:25,656 basehttp 2288 45576 "GET /admin/jsi18n/ HTTP/1.1" 200 3342
INFO 2025-08-28 16:56:33,970 basehttp 2288 45576 "POST /admin/auth/user/2/change/ HTTP/1.1" 302 0
INFO 2025-08-28 16:56:34,245 basehttp 2288 45576 "GET /admin/auth/user/ HTTP/1.1" 200 40094
INFO 2025-08-28 16:56:34,436 basehttp 2288 45576 "GET /admin/jsi18n/ HTTP/1.1" 200 3342
INFO 2025-08-28 16:56:37,022 basehttp 2288 45576 "GET /admin/core/apppermission/ HTTP/1.1" 200 34679
INFO 2025-08-28 16:56:37,186 basehttp 2288 45576 "GET /admin/jsi18n/ HTTP/1.1" 200 3342
INFO 2025-08-28 16:56:39,180 basehttp 2288 45576 "GET /admin/core/apppermission/add/ HTTP/1.1" 200 37193
INFO 2025-08-28 16:56:39,237 basehttp 2288 11864 "GET /static/admin/css/vendor/select2/select2.css HTTP/1.1" 200 17358
INFO 2025-08-28 16:56:39,238 basehttp 2288 32580 "GET /static/admin/js/autocomplete.js HTTP/1.1" 200 1060
INFO 2025-08-28 16:56:39,239 basehttp 2288 45248 "GET /static/admin/js/vendor/select2/i18n/en.js HTTP/1.1" 200 844
INFO 2025-08-28 16:56:39,239 basehttp 2288 2200 "GET /static/admin/css/autocomplete.css HTTP/1.1" 200 9185
INFO 2025-08-28 16:56:39,247 basehttp 2288 4388 "GET /static/admin/js/vendor/select2/select2.full.js HTTP/1.1" 200 173566
INFO 2025-08-28 16:56:39,370 basehttp 2288 45576 "GET /admin/jsi18n/ HTTP/1.1" 200 3342
INFO 2025-08-28 16:56:41,123 basehttp 2288 45576 "GET /admin/autocomplete/?app_label=core&model_name=apppermission&field_name=role HTTP/1.1" 200 46
INFO 2025-08-28 16:56:42,613 basehttp 2288 45576 "GET /admin/autocomplete/?app_label=core&model_name=apppermission&field_name=role HTTP/1.1" 200 46
INFO 2025-08-28 16:56:43,080 basehttp 2288 45576 "GET /admin/autocomplete/?app_label=core&model_name=apppermission&field_name=role HTTP/1.1" 200 46
INFO 2025-08-28 16:56:53,787 basehttp 2288 45576 "GET /admin/core/employeerole/add/?_to_field=id&_popup=1 HTTP/1.1" 200 9809
INFO 2025-08-28 16:56:53,958 basehttp 2288 45576 "GET /admin/jsi18n/ HTTP/1.1" 200 3342
INFO 2025-08-28 16:57:36,065 basehttp 2288 45576 "POST /admin/core/employeerole/add/?_to_field=id&_popup=1 HTTP/1.1" 200 340
INFO 2025-08-28 16:57:36,096 basehttp 2288 45576 "GET /static/admin/js/popup_response.js HTTP/1.1" 200 532
INFO 2025-08-28 16:57:38,859 basehttp 2288 45576 "GET /admin/autocomplete/?app_label=core&model_name=apppermission&field_name=role HTTP/1.1" 200 89
INFO 2025-08-28 16:57:40,804 basehttp 2288 45576 "GET /admin/core/employeerole/add/?_to_field=id&_popup=1 HTTP/1.1" 200 9809
INFO 2025-08-28 16:57:40,989 basehttp 2288 45576 "GET /admin/jsi18n/ HTTP/1.1" 200 3342
INFO 2025-08-28 16:58:05,897 basehttp 2288 45576 "POST /admin/core/employeerole/add/?_to_field=id&_popup=1 HTTP/1.1" 200 337
INFO 2025-08-28 16:58:07,547 basehttp 2288 45576 "GET /admin/autocomplete/?app_label=core&model_name=apppermission&field_name=role HTTP/1.1" 200 131
INFO 2025-08-28 16:58:09,306 basehttp 2288 45576 "GET /admin/core/employeerole/add/?_to_field=id&_popup=1 HTTP/1.1" 200 9809
INFO 2025-08-28 16:58:09,491 basehttp 2288 45576 "GET /admin/jsi18n/ HTTP/1.1" 200 3342
INFO 2025-08-28 16:58:42,501 basehttp 2288 45576 "POST /admin/core/employeerole/add/?_to_field=id&_popup=1 HTTP/1.1" 200 333
INFO 2025-08-28 16:58:44,889 basehttp 2288 45576 "GET /admin/core/employeerole/add/?_to_field=id&_popup=1 HTTP/1.1" 200 9809
INFO 2025-08-28 16:58:45,070 basehttp 2288 45576 "GET /admin/jsi18n/ HTTP/1.1" 200 3342
INFO 2025-08-28 16:59:14,633 basehttp 2288 45576 "POST /admin/core/employeerole/add/?_to_field=id&_popup=1 HTTP/1.1" 200 361
INFO 2025-08-28 16:59:17,160 basehttp 2288 45576 "GET /admin/autocomplete/?app_label=core&model_name=apppermission&field_name=role HTTP/1.1" 200 235
INFO 2025-08-28 16:59:26,156 basehttp 2288 45576 "POST /admin/core/apppermission/add/ HTTP/1.1" 302 0
INFO 2025-08-28 16:59:26,461 basehttp 2288 45576 "GET /admin/core/apppermission/ HTTP/1.1" 200 38156
INFO 2025-08-28 16:59:26,645 basehttp 2288 45576 "GET /admin/jsi18n/ HTTP/1.1" 200 3342
INFO 2025-08-28 16:59:30,823 basehttp 2288 45576 "GET /admin/core/apppermission/1/change/ HTTP/1.1" 200 37594
INFO 2025-08-28 16:59:30,997 basehttp 2288 45576 "GET /admin/jsi18n/ HTTP/1.1" 200 3342
INFO 2025-08-28 16:59:35,317 basehttp 2288 45576 "POST /admin/core/apppermission/1/change/ HTTP/1.1" 302 0
INFO 2025-08-28 16:59:35,627 basehttp 2288 45576 "GET /admin/core/apppermission/ HTTP/1.1" 200 38188
INFO 2025-08-28 16:59:35,799 basehttp 2288 45576 "GET /admin/jsi18n/ HTTP/1.1" 200 3342
INFO 2025-08-28 16:59:40,574 basehttp 2288 45576 "GET /admin/core/apppermission/add/ HTTP/1.1" 200 37193
INFO 2025-08-28 16:59:40,737 basehttp 2288 45576 "GET /admin/jsi18n/ HTTP/1.1" 200 3342
INFO 2025-08-28 16:59:41,890 basehttp 2288 45576 "GET /admin/autocomplete/?app_label=core&model_name=apppermission&field_name=role HTTP/1.1" 200 235
INFO 2025-08-28 16:59:49,008 basehttp 2288 45576 "POST /admin/core/apppermission/add/ HTTP/1.1" 200 37428
INFO 2025-08-28 16:59:49,206 basehttp 2288 45576 "GET /admin/jsi18n/ HTTP/1.1" 200 3342
INFO 2025-08-28 16:59:56,205 basehttp 2288 45576 "POST /admin/core/apppermission/add/ HTTP/1.1" 302 0
INFO 2025-08-28 16:59:56,508 basehttp 2288 45576 "GET /admin/core/apppermission/ HTTP/1.1" 200 38712
INFO 2025-08-28 16:59:56,684 basehttp 2288 45576 "GET /admin/jsi18n/ HTTP/1.1" 200 3342
INFO 2025-08-28 16:59:58,779 basehttp 2288 45576 "GET /admin/core/apppermission/add/ HTTP/1.1" 200 37193
INFO 2025-08-28 16:59:58,966 basehttp 2288 45576 "GET /admin/jsi18n/ HTTP/1.1" 200 3342
INFO 2025-08-28 17:00:00,076 basehttp 2288 45576 "GET /admin/autocomplete/?app_label=core&model_name=apppermission&field_name=role HTTP/1.1" 200 235
INFO 2025-08-28 17:00:07,554 basehttp 2288 45576 "POST /admin/core/apppermission/add/ HTTP/1.1" 302 0
INFO 2025-08-28 17:00:07,834 basehttp 2288 45576 "GET /admin/core/apppermission/ HTTP/1.1" 200 39268
INFO 2025-08-28 17:00:08,014 basehttp 2288 45576 "GET /admin/jsi18n/ HTTP/1.1" 200 3342
INFO 2025-08-28 17:00:09,712 basehttp 2288 45576 "GET /admin/core/apppermission/add/ HTTP/1.1" 200 37193
INFO 2025-08-28 17:00:09,891 basehttp 2288 45576 "GET /admin/jsi18n/ HTTP/1.1" 200 3342
INFO 2025-08-28 17:00:11,097 basehttp 2288 45576 "GET /admin/autocomplete/?app_label=core&model_name=apppermission&field_name=role HTTP/1.1" 200 235
INFO 2025-08-28 17:00:19,942 basehttp 2288 45576 "POST /admin/core/apppermission/add/ HTTP/1.1" 302 0
INFO 2025-08-28 17:00:20,233 basehttp 2288 45576 "GET /admin/core/apppermission/ HTTP/1.1" 200 39810
INFO 2025-08-28 17:00:20,415 basehttp 2288 45576 "GET /admin/jsi18n/ HTTP/1.1" 200 3342
INFO 2025-08-28 17:00:25,079 basehttp 2288 45576 "GET /admin/core/apppermission/add/ HTTP/1.1" 200 37193
INFO 2025-08-28 17:00:25,249 basehttp 2288 45576 "GET /admin/jsi18n/ HTTP/1.1" 200 3342
INFO 2025-08-28 17:00:26,127 basehttp 2288 45576 "GET /admin/autocomplete/?app_label=core&model_name=apppermission&field_name=role HTTP/1.1" 200 235
INFO 2025-08-28 17:00:37,299 basehttp 2288 45576 "POST /admin/core/apppermission/add/ HTTP/1.1" 302 0
INFO 2025-08-28 17:00:37,560 basehttp 2288 45576 "GET /admin/core/apppermission/ HTTP/1.1" 200 40339
INFO 2025-08-28 17:00:37,737 basehttp 2288 45576 "GET /admin/jsi18n/ HTTP/1.1" 200 3342
INFO 2025-08-28 17:00:40,355 basehttp 2288 45576 "GET /admin/core/approvalrequest/ HTTP/1.1" 200 35602
INFO 2025-08-28 17:00:40,528 basehttp 2288 45576 "GET /admin/jsi18n/ HTTP/1.1" 200 3342
INFO 2025-08-28 17:00:42,216 basehttp 2288 45576 "GET /admin/core/employeerole/ HTTP/1.1" 200 38455
INFO 2025-08-28 17:00:42,256 basehttp 2288 4388 "GET /static/admin/img/icon-no.svg HTTP/1.1" 200 560
INFO 2025-08-28 17:00:42,405 basehttp 2288 45576 "GET /admin/jsi18n/ HTTP/1.1" 200 3342
INFO 2025-08-28 17:00:53,402 basehttp 2288 45576 "GET /admin/core/systemsetting/ HTTP/1.1" 200 33818
INFO 2025-08-28 17:00:53,573 basehttp 2288 45576 "GET /admin/jsi18n/ HTTP/1.1" 200 3342
INFO 2025-08-28 17:00:55,762 basehttp 2288 45576 "GET /admin/core/systemsetting/add/ HTTP/1.1" 200 37091
INFO 2025-08-28 17:00:55,942 basehttp 2288 45576 "GET /admin/jsi18n/ HTTP/1.1" 200 3342
INFO 2025-08-28 17:00:59,364 basehttp 2288 45576 "GET /admin/core/userprofile/ HTTP/1.1" 200 37114
INFO 2025-08-28 17:00:59,536 basehttp 2288 45576 "GET /admin/jsi18n/ HTTP/1.1" 200 3342
INFO 2025-08-28 17:01:04,487 basehttp 2288 45576 "GET /admin/core/userrole/ HTTP/1.1" 200 34096
INFO 2025-08-28 17:01:04,671 basehttp 2288 45576 "GET /admin/jsi18n/ HTTP/1.1" 200 3342
INFO 2025-08-28 17:01:06,592 basehttp 2288 45576 "GET /admin/core/userrole/add/ HTTP/1.1" 200 39747
INFO 2025-08-28 17:01:06,635 basehttp 2288 4388 "GET /static/admin/img/icon-deletelink.svg HTTP/1.1" 200 392
INFO 2025-08-28 17:01:06,843 basehttp 2288 45576 "GET /admin/jsi18n/ HTTP/1.1" 200 3342
INFO 2025-08-28 17:01:16,244 basehttp 2288 45576 "POST /admin/core/userrole/add/ HTTP/1.1" 302 0
INFO 2025-08-28 17:01:16,594 basehttp 2288 45576 "GET /admin/core/userrole/ HTTP/1.1" 200 36699
INFO 2025-08-28 17:01:16,793 basehttp 2288 45576 "GET /admin/jsi18n/ HTTP/1.1" 200 3342
INFO 2025-08-28 17:01:18,603 basehttp 2288 45576 "GET /admin/core/userrole/add/ HTTP/1.1" 200 39747
INFO 2025-08-28 17:01:18,773 basehttp 2288 45576 "GET /admin/jsi18n/ HTTP/1.1" 200 3342
INFO 2025-08-28 17:01:26,666 basehttp 2288 45576 "POST /admin/core/userrole/add/ HTTP/1.1" 302 0
INFO 2025-08-28 17:01:26,957 basehttp 2288 45576 "GET /admin/core/userrole/ HTTP/1.1" 200 37247
INFO 2025-08-28 17:01:27,140 basehttp 2288 45576 "GET /admin/jsi18n/ HTTP/1.1" 200 3342
INFO 2025-08-28 17:01:34,815 basehttp 2288 45576 "GET /admin/core/userrole/1/change/ HTTP/1.1" 200 40020
INFO 2025-08-28 17:01:34,984 basehttp 2288 45576 "GET /admin/jsi18n/ HTTP/1.1" 200 3342
INFO 2025-08-28 17:01:42,290 basehttp 2288 45576 "GET /admin/ HTTP/1.1" 200 43942
INFO 2025-08-28 17:01:46,165 basehttp 2288 45576 "GET /admin/auth/user/ HTTP/1.1" 200 39886
INFO 2025-08-28 17:01:46,359 basehttp 2288 45576 "GET /admin/jsi18n/ HTTP/1.1" 200 3342
INFO 2025-08-28 17:01:48,483 basehttp 2288 45576 "GET /admin/auth/user/1/change/ HTTP/1.1" 200 78681
INFO 2025-08-28 17:01:48,664 basehttp 2288 45576 "GET /admin/jsi18n/ HTTP/1.1" 200 3342
INFO 2025-08-28 17:02:05,053 basehttp 2288 45576 "GET / HTTP/1.1" 200 34194
WARNING 2025-08-28 17:02:05,104 basehttp 2288 45576 "GET /static/website/img/portfolio-1.jpg HTTP/1.1" 404 2008
WARNING 2025-08-28 17:02:05,139 basehttp 2288 4388 "GET /static/website/img/portfolio-2.jpg HTTP/1.1" 404 2008
WARNING 2025-08-28 17:02:05,169 basehttp 2288 23512 "GET /static/website/img/portfolio-3.jpg HTTP/1.1" 404 2008
WARNING 2025-08-28 17:02:05,196 basehttp 2288 44732 "GET /static/website/img/client-1.jpg HTTP/1.1" 404 1999
WARNING 2025-08-28 17:02:05,201 basehttp 2288 35016 "GET /static/website/img/client-2.jpg HTTP/1.1" 404 1999
WARNING 2025-08-28 17:02:05,222 basehttp 2288 38668 "GET /static/website/img/client-3.jpg HTTP/1.1" 404 1999
WARNING 2025-08-28 17:02:05,264 basehttp 2288 42820 "GET /static/website/img/partner-1.png HTTP/1.1" 404 2002
WARNING 2025-08-28 17:02:05,265 basehttp 2288 44352 "GET /static/website/img/partner-2.png HTTP/1.1" 404 2002
WARNING 2025-08-28 17:02:05,309 basehttp 2288 36232 "GET /static/website/img/partner-4.png HTTP/1.1" 404 2002
WARNING 2025-08-28 17:02:05,323 basehttp 2288 46132 "GET /static/website/img/partner-5.png HTTP/1.1" 404 2002
WARNING 2025-08-28 17:02:05,342 basehttp 2288 35104 "GET /static/website/img/partner-3.png HTTP/1.1" 404 2002
WARNING 2025-08-28 17:02:05,344 basehttp 2288 37404 "GET /static/website/img/partner-6.png HTTP/1.1" 404 2002
INFO 2025-08-28 17:02:08,207 basehttp 2288 40204 "GET /auth/dashboard/ HTTP/1.1" 200 45643
INFO 2025-08-28 17:02:08,256 basehttp 2288 40204 "GET /static/core/css/dashboard.css HTTP/1.1" 200 16172
INFO 2025-08-28 17:02:08,259 basehttp 2288 4564 "GET /static/core/img/blitz-logo.png HTTP/1.1" 200 9495
INFO 2025-08-28 17:02:08,261 basehttp 2288 44152 "GET /static/core/js/dashboard.js HTTP/1.1" 200 22916
INFO 2025-08-28 17:02:10,518 basehttp 2288 44152 "GET /crm/ HTTP/1.1" 200 44073
INFO 2025-08-28 17:02:12,127 basehttp 2288 44152 "GET /quotes/ HTTP/1.1" 200 33142
INFO 2025-08-28 17:02:14,163 basehttp 2288 44152 "GET /crm/ HTTP/1.1" 200 44073
INFO 2025-08-28 17:02:15,283 basehttp 2288 44152 "GET /quotes/ HTTP/1.1" 200 33142
INFO 2025-08-28 17:02:16,584 basehttp 2288 44152 "GET /inventory/ HTTP/1.1" 200 37473
INFO 2025-08-28 17:02:18,595 basehttp 2288 44152 "GET /inventory/ HTTP/1.1" 200 37473
INFO 2025-08-28 17:02:20,299 basehttp 2288 44152 "GET /admin-dashboard/ HTTP/1.1" 200 45134
INFO 2025-08-28 17:02:23,319 basehttp 2288 44152 "GET /auth/audit-logs/ HTTP/1.1" 200 33812
INFO 2025-08-28 17:02:26,845 basehttp 2288 44152 "GET /inventory/ HTTP/1.1" 200 37473
INFO 2025-08-28 17:02:34,606 basehttp 2288 44152 "GET /inventory/products/create/ HTTP/1.1" 200 54500
INFO 2025-08-28 17:02:46,344 basehttp 2288 44152 "GET /inventory/products/ HTTP/1.1" 200 36870
INFO 2025-08-28 17:02:52,143 basehttp 2288 44152 "GET /inventory/ HTTP/1.1" 200 37473
ERROR 2025-08-28 17:02:56,446 log 2288 44152 Internal Server Error: /inventory/barcodes/scanner/
Traceback (most recent call last):
  File "C:\Local Disk E\BlitzTech Systems\erpdev\venv\lib\site-packages\django\core\handlers\exception.py", line 55, in inner
    response = get_response(request)
  File "C:\Local Disk E\BlitzTech Systems\erpdev\venv\lib\site-packages\django\core\handlers\base.py", line 220, in _get_response
    response = response.render()
  File "C:\Local Disk E\BlitzTech Systems\erpdev\venv\lib\site-packages\django\template\response.py", line 114, in render
    self.content = self.rendered_content
  File "C:\Local Disk E\BlitzTech Systems\erpdev\venv\lib\site-packages\django\template\response.py", line 90, in rendered_content
    template = self.resolve_template(self.template_name)
  File "C:\Local Disk E\BlitzTech Systems\erpdev\venv\lib\site-packages\django\template\response.py", line 72, in resolve_template
    return select_template(template, using=self.using)
  File "C:\Local Disk E\BlitzTech Systems\erpdev\venv\lib\site-packages\django\template\loader.py", line 47, in select_template
    raise TemplateDoesNotExist(", ".join(template_name_list), chain=chain)
django.template.exceptions.TemplateDoesNotExist: inventory/barcode/barcode_scanner.html
ERROR 2025-08-28 17:02:56,456 basehttp 2288 44152 "GET /inventory/barcodes/scanner/ HTTP/1.1" 500 128900
WARNING 2025-08-28 17:02:58,713 log 2288 44152 Bad Request: /auth/api/get-notification-count/
WARNING 2025-08-28 17:02:58,716 basehttp 2288 44152 "GET /auth/api/get-notification-count/ HTTP/1.1" 400 34
WARNING 2025-08-28 17:02:58,922 log 2288 4564 Bad Request: /auth/api/get-notification-count/
WARNING 2025-08-28 17:02:58,929 basehttp 2288 4564 "GET /auth/api/get-notification-count/ HTTP/1.1" 400 34
ERROR 2025-08-28 17:03:05,482 log 2288 4564 Internal Server Error: /inventory/stock/adjust/
Traceback (most recent call last):
  File "C:\Local Disk E\BlitzTech Systems\erpdev\venv\lib\site-packages\django\core\handlers\exception.py", line 55, in inner
    response = get_response(request)
  File "C:\Local Disk E\BlitzTech Systems\erpdev\venv\lib\site-packages\django\utils\deprecation.py", line 131, in __call__
    response = self.process_response(request, response)
  File "C:\Local Disk E\BlitzTech Systems\erpdev\venv\lib\site-packages\django\middleware\clickjacking.py", line 27, in process_response
    if response.get("X-Frame-Options") is not None:
AttributeError: 'function' object has no attribute 'get'
ERROR 2025-08-28 17:03:05,486 basehttp 2288 4564 "GET /inventory/stock/adjust/ HTTP/1.1" 500 107240
WARNING 2025-08-28 17:03:07,532 log 2288 4564 Bad Request: /auth/api/get-notification-count/
WARNING 2025-08-28 17:03:07,533 basehttp 2288 4564 "GET /auth/api/get-notification-count/ HTTP/1.1" 400 34
WARNING 2025-08-28 17:03:07,698 log 2288 44152 Bad Request: /auth/api/get-notification-count/
WARNING 2025-08-28 17:03:07,701 basehttp 2288 44152 "GET /auth/api/get-notification-count/ HTTP/1.1" 400 34
INFO 2025-08-28 17:03:08,810 basehttp 2288 44152 "GET /inventory/products/create/ HTTP/1.1" 200 54500
INFO 2025-08-28 17:03:22,379 basehttp 2288 44152 "GET /inventory/products/ HTTP/1.1" 200 36870
INFO 2025-08-28 17:03:25,276 basehttp 2288 44152 "GET /auth/dashboard/ HTTP/1.1" 200 45643
INFO 2025-08-28 17:03:36,594 basehttp 2288 44152 "GET /admin/inventory/supplier/ HTTP/1.1" 200 34218
INFO 2025-08-28 17:03:36,766 basehttp 2288 44152 "GET /admin/jsi18n/ HTTP/1.1" 200 3342
ERROR 2025-08-28 17:03:38,897 log 2288 44152 Internal Server Error: /admin/inventory/supplier/add/
Traceback (most recent call last):
  File "C:\Local Disk E\BlitzTech Systems\erpdev\venv\lib\site-packages\django\contrib\admin\options.py", line 839, in get_form
    return modelform_factory(self.model, **defaults)
  File "C:\Local Disk E\BlitzTech Systems\erpdev\venv\lib\site-packages\django\forms\models.py", line 654, in modelform_factory
    return type(form)(class_name, (form,), form_class_attrs)
  File "C:\Local Disk E\BlitzTech Systems\erpdev\venv\lib\site-packages\django\forms\models.py", line 334, in __new__
    raise FieldError(message)
django.core.exceptions.FieldError: Unknown field(s) (address) specified for Supplier

During handling of the above exception, another exception occurred:

Traceback (most recent call last):
  File "C:\Local Disk E\BlitzTech Systems\erpdev\venv\lib\site-packages\django\core\handlers\exception.py", line 55, in inner
    response = get_response(request)
  File "C:\Local Disk E\BlitzTech Systems\erpdev\venv\lib\site-packages\django\core\handlers\base.py", line 197, in _get_response
    response = wrapped_callback(request, *callback_args, **callback_kwargs)
  File "C:\Local Disk E\BlitzTech Systems\erpdev\venv\lib\site-packages\django\contrib\admin\options.py", line 718, in wrapper
    return self.admin_site.admin_view(view)(*args, **kwargs)
  File "C:\Local Disk E\BlitzTech Systems\erpdev\venv\lib\site-packages\django\utils\decorators.py", line 188, in _view_wrapper
    result = _process_exception(request, e)
  File "C:\Local Disk E\BlitzTech Systems\erpdev\venv\lib\site-packages\django\utils\decorators.py", line 186, in _view_wrapper
    response = view_func(request, *args, **kwargs)
  File "C:\Local Disk E\BlitzTech Systems\erpdev\venv\lib\site-packages\django\views\decorators\cache.py", line 80, in _view_wrapper
    response = view_func(request, *args, **kwargs)
  File "C:\Local Disk E\BlitzTech Systems\erpdev\venv\lib\site-packages\django\contrib\admin\sites.py", line 241, in inner
    return view(request, *args, **kwargs)
  File "C:\Local Disk E\BlitzTech Systems\erpdev\venv\lib\site-packages\django\contrib\admin\options.py", line 1961, in add_view
    return self.changeform_view(request, None, form_url, extra_context)
  File "C:\Local Disk E\BlitzTech Systems\erpdev\venv\lib\site-packages\django\utils\decorators.py", line 48, in _wrapper
    return bound_method(*args, **kwargs)
  File "C:\Local Disk E\BlitzTech Systems\erpdev\venv\lib\site-packages\django\utils\decorators.py", line 188, in _view_wrapper
    result = _process_exception(request, e)
  File "C:\Local Disk E\BlitzTech Systems\erpdev\venv\lib\site-packages\django\utils\decorators.py", line 186, in _view_wrapper
    response = view_func(request, *args, **kwargs)
  File "C:\Local Disk E\BlitzTech Systems\erpdev\venv\lib\site-packages\django\contrib\admin\options.py", line 1820, in changeform_view
    return self._changeform_view(request, object_id, form_url, extra_context)
  File "C:\Local Disk E\BlitzTech Systems\erpdev\venv\lib\site-packages\django\contrib\admin\options.py", line 1855, in _changeform_view
    ModelForm = self.get_form(
  File "C:\Local Disk E\BlitzTech Systems\erpdev\venv\lib\site-packages\django\contrib\admin\options.py", line 841, in get_form
    raise FieldError(
django.core.exceptions.FieldError: Unknown field(s) (address) specified for Supplier. Check fields/fieldsets/exclude attributes of class SupplierAdmin.
ERROR 2025-08-28 17:03:38,916 basehttp 2288 44152 "GET /admin/inventory/supplier/add/ HTTP/1.1" 500 193531
INFO 2025-08-28 17:03:43,014 basehttp 2288 44152 "GET /admin/inventory/supplier/ HTTP/1.1" 200 34218
WARNING 2025-08-28 17:03:45,526 log 2288 44152 Bad Request: /auth/api/get-notification-count/
WARNING 2025-08-28 17:03:45,530 basehttp 2288 44152 "GET /auth/api/get-notification-count/ HTTP/1.1" 400 34
INFO 2025-08-28 17:03:53,332 basehttp 2288 44152 "GET /auth/notifications/ HTTP/1.1" 200 47579
INFO 2025-08-28 17:04:03,168 basehttp 2288 44152 "GET /auth/dashboard/ HTTP/1.1" 200 45643
WARNING 2025-08-28 17:05:21,426 log 2288 27812 Bad Request: /auth/api/get-notification-count/
WARNING 2025-08-28 17:05:21,429 basehttp 2288 27812 "GET /auth/api/get-notification-count/ HTTP/1.1" 400 34
WARNING 2025-08-28 17:07:42,243 log 2288 27812 Bad Request: /auth/api/get-notification-count/
WARNING 2025-08-28 17:07:42,247 basehttp 2288 27812 "GET /auth/api/get-notification-count/ HTTP/1.1" 400 34
WARNING 2025-08-28 17:09:03,987 log 2288 27812 Bad Request: /auth/api/get-notification-count/
WARNING 2025-08-28 17:09:03,990 basehttp 2288 27812 "GET /auth/api/get-notification-count/ HTTP/1.1" 400 34
WARNING 2025-08-28 17:14:04,004 log 2288 27812 Bad Request: /auth/api/get-notification-count/
WARNING 2025-08-28 17:14:04,007 basehttp 2288 27812 "GET /auth/api/get-notification-count/ HTTP/1.1" 400 34
ERROR 2025-08-28 17:19:32,413 log 2288 27812 Internal Server Error: /auth/api/get-notification-count/
Traceback (most recent call last):
  File "C:\Local Disk E\BlitzTech Systems\erpdev\venv\lib\site-packages\django\contrib\sessions\backends\base.py", line 244, in _get_session
    return self._session_cache
AttributeError: 'SessionStore' object has no attribute '_session_cache'

During handling of the above exception, another exception occurred:

Traceback (most recent call last):
  File "C:\Local Disk E\BlitzTech Systems\erpdev\venv\lib\site-packages\django\db\backends\base\base.py", line 279, in ensure_connection
    self.connect()
  File "C:\Local Disk E\BlitzTech Systems\erpdev\venv\lib\site-packages\django\utils\asyncio.py", line 26, in inner
    return func(*args, **kwargs)
  File "C:\Local Disk E\BlitzTech Systems\erpdev\venv\lib\site-packages\django\db\backends\base\base.py", line 256, in connect
    self.connection = self.get_new_connection(conn_params)
  File "C:\Local Disk E\BlitzTech Systems\erpdev\venv\lib\site-packages\django\utils\asyncio.py", line 26, in inner
    return func(*args, **kwargs)
  File "C:\Local Disk E\BlitzTech Systems\erpdev\venv\lib\site-packages\django\db\backends\postgresql\base.py", line 332, in get_new_connection
    connection = self.Database.connect(**conn_params)
  File "C:\Local Disk E\BlitzTech Systems\erpdev\venv\lib\site-packages\psycopg2\__init__.py", line 122, in connect
    conn = _connect(dsn, connection_factory=connection_factory, **kwasync)
psycopg2.OperationalError: connection to server at "localhost" (::1), port 5432 failed: Connection refused (0x0000274D/10061)
	Is the server running on that host and accepting TCP/IP connections?
connection to server at "localhost" (127.0.0.1), port 5432 failed: Connection refused (0x0000274D/10061)
	Is the server running on that host and accepting TCP/IP connections?


The above exception was the direct cause of the following exception:

Traceback (most recent call last):
  File "C:\Local Disk E\BlitzTech Systems\erpdev\venv\lib\site-packages\django\core\handlers\exception.py", line 55, in inner
    response = get_response(request)
  File "C:\Local Disk E\BlitzTech Systems\erpdev\venv\lib\site-packages\django\utils\deprecation.py", line 131, in __call__
    response = self.process_response(request, response)
  File "C:\Local Disk E\BlitzTech Systems\erpdev\venv\lib\site-packages\django\contrib\sessions\middleware.py", line 48, in process_response
    if request.session.get_expire_at_browser_close():
  File "C:\Local Disk E\BlitzTech Systems\erpdev\venv\lib\site-packages\django\contrib\sessions\backends\base.py", line 403, in get_expire_at_browser_close
    if (expiry := self.get("_session_expiry")) is None:
  File "C:\Local Disk E\BlitzTech Systems\erpdev\venv\lib\site-packages\django\contrib\sessions\backends\base.py", line 74, in get
    return self._session.get(key, default)
  File "C:\Local Disk E\BlitzTech Systems\erpdev\venv\lib\site-packages\django\contrib\sessions\backends\base.py", line 249, in _get_session
    self._session_cache = self.load()
  File "C:\Local Disk E\BlitzTech Systems\erpdev\venv\lib\site-packages\django\contrib\sessions\backends\db.py", line 55, in load
    s = self._get_session_from_db()
  File "C:\Local Disk E\BlitzTech Systems\erpdev\venv\lib\site-packages\django\contrib\sessions\backends\db.py", line 34, in _get_session_from_db
    return self.model.objects.get(
  File "C:\Local Disk E\BlitzTech Systems\erpdev\venv\lib\site-packages\django\db\models\manager.py", line 87, in manager_method
    return getattr(self.get_queryset(), name)(*args, **kwargs)
  File "C:\Local Disk E\BlitzTech Systems\erpdev\venv\lib\site-packages\django\db\models\query.py", line 645, in get
    num = len(clone)
  File "C:\Local Disk E\BlitzTech Systems\erpdev\venv\lib\site-packages\django\db\models\query.py", line 382, in __len__
    self._fetch_all()
  File "C:\Local Disk E\BlitzTech Systems\erpdev\venv\lib\site-packages\django\db\models\query.py", line 1928, in _fetch_all
    self._result_cache = list(self._iterable_class(self))
  File "C:\Local Disk E\BlitzTech Systems\erpdev\venv\lib\site-packages\django\db\models\query.py", line 91, in __iter__
    results = compiler.execute_sql(
  File "C:\Local Disk E\BlitzTech Systems\erpdev\venv\lib\site-packages\django\db\models\sql\compiler.py", line 1572, in execute_sql
    cursor = self.connection.cursor()
  File "C:\Local Disk E\BlitzTech Systems\erpdev\venv\lib\site-packages\django\utils\asyncio.py", line 26, in inner
    return func(*args, **kwargs)
  File "C:\Local Disk E\BlitzTech Systems\erpdev\venv\lib\site-packages\django\db\backends\base\base.py", line 320, in cursor
    return self._cursor()
  File "C:\Local Disk E\BlitzTech Systems\erpdev\venv\lib\site-packages\django\db\backends\base\base.py", line 296, in _cursor
    self.ensure_connection()
  File "C:\Local Disk E\BlitzTech Systems\erpdev\venv\lib\site-packages\django\utils\asyncio.py", line 26, in inner
    return func(*args, **kwargs)
  File "C:\Local Disk E\BlitzTech Systems\erpdev\venv\lib\site-packages\django\db\backends\base\base.py", line 278, in ensure_connection
    with self.wrap_database_errors:
  File "C:\Local Disk E\BlitzTech Systems\erpdev\venv\lib\site-packages\django\db\utils.py", line 91, in __exit__
    raise dj_exc_value.with_traceback(traceback) from exc_value
  File "C:\Local Disk E\BlitzTech Systems\erpdev\venv\lib\site-packages\django\db\backends\base\base.py", line 279, in ensure_connection
    self.connect()
  File "C:\Local Disk E\BlitzTech Systems\erpdev\venv\lib\site-packages\django\utils\asyncio.py", line 26, in inner
    return func(*args, **kwargs)
  File "C:\Local Disk E\BlitzTech Systems\erpdev\venv\lib\site-packages\django\db\backends\base\base.py", line 256, in connect
    self.connection = self.get_new_connection(conn_params)
  File "C:\Local Disk E\BlitzTech Systems\erpdev\venv\lib\site-packages\django\utils\asyncio.py", line 26, in inner
    return func(*args, **kwargs)
  File "C:\Local Disk E\BlitzTech Systems\erpdev\venv\lib\site-packages\django\db\backends\postgresql\base.py", line 332, in get_new_connection
    connection = self.Database.connect(**conn_params)
  File "C:\Local Disk E\BlitzTech Systems\erpdev\venv\lib\site-packages\psycopg2\__init__.py", line 122, in connect
    conn = _connect(dsn, connection_factory=connection_factory, **kwasync)
django.db.utils.OperationalError: connection to server at "localhost" (::1), port 5432 failed: Connection refused (0x0000274D/10061)
	Is the server running on that host and accepting TCP/IP connections?
connection to server at "localhost" (127.0.0.1), port 5432 failed: Connection refused (0x0000274D/10061)
	Is the server running on that host and accepting TCP/IP connections?

ERROR 2025-08-28 17:19:32,428 basehttp 2288 27812 "GET /auth/api/get-notification-count/ HTTP/1.1" 500 237977
ERROR 2025-08-28 17:23:43,089 log 2288 32092 Internal Server Error: /auth/api/get-notification-count/
Traceback (most recent call last):
  File "C:\Local Disk E\BlitzTech Systems\erpdev\venv\lib\site-packages\django\contrib\sessions\backends\base.py", line 244, in _get_session
    return self._session_cache
AttributeError: 'SessionStore' object has no attribute '_session_cache'

During handling of the above exception, another exception occurred:

Traceback (most recent call last):
  File "C:\Local Disk E\BlitzTech Systems\erpdev\venv\lib\site-packages\django\db\backends\base\base.py", line 279, in ensure_connection
    self.connect()
  File "C:\Local Disk E\BlitzTech Systems\erpdev\venv\lib\site-packages\django\utils\asyncio.py", line 26, in inner
    return func(*args, **kwargs)
  File "C:\Local Disk E\BlitzTech Systems\erpdev\venv\lib\site-packages\django\db\backends\base\base.py", line 256, in connect
    self.connection = self.get_new_connection(conn_params)
  File "C:\Local Disk E\BlitzTech Systems\erpdev\venv\lib\site-packages\django\utils\asyncio.py", line 26, in inner
    return func(*args, **kwargs)
  File "C:\Local Disk E\BlitzTech Systems\erpdev\venv\lib\site-packages\django\db\backends\postgresql\base.py", line 332, in get_new_connection
    connection = self.Database.connect(**conn_params)
  File "C:\Local Disk E\BlitzTech Systems\erpdev\venv\lib\site-packages\psycopg2\__init__.py", line 122, in connect
    conn = _connect(dsn, connection_factory=connection_factory, **kwasync)
psycopg2.OperationalError: connection to server at "localhost" (::1), port 5432 failed: Connection refused (0x0000274D/10061)
	Is the server running on that host and accepting TCP/IP connections?
connection to server at "localhost" (127.0.0.1), port 5432 failed: Connection refused (0x0000274D/10061)
	Is the server running on that host and accepting TCP/IP connections?


The above exception was the direct cause of the following exception:

Traceback (most recent call last):
  File "C:\Local Disk E\BlitzTech Systems\erpdev\venv\lib\site-packages\django\core\handlers\exception.py", line 55, in inner
    response = get_response(request)
  File "C:\Local Disk E\BlitzTech Systems\erpdev\venv\lib\site-packages\django\utils\deprecation.py", line 131, in __call__
    response = self.process_response(request, response)
  File "C:\Local Disk E\BlitzTech Systems\erpdev\venv\lib\site-packages\django\contrib\sessions\middleware.py", line 48, in process_response
    if request.session.get_expire_at_browser_close():
  File "C:\Local Disk E\BlitzTech Systems\erpdev\venv\lib\site-packages\django\contrib\sessions\backends\base.py", line 403, in get_expire_at_browser_close
    if (expiry := self.get("_session_expiry")) is None:
  File "C:\Local Disk E\BlitzTech Systems\erpdev\venv\lib\site-packages\django\contrib\sessions\backends\base.py", line 74, in get
    return self._session.get(key, default)
  File "C:\Local Disk E\BlitzTech Systems\erpdev\venv\lib\site-packages\django\contrib\sessions\backends\base.py", line 249, in _get_session
    self._session_cache = self.load()
  File "C:\Local Disk E\BlitzTech Systems\erpdev\venv\lib\site-packages\django\contrib\sessions\backends\db.py", line 55, in load
    s = self._get_session_from_db()
  File "C:\Local Disk E\BlitzTech Systems\erpdev\venv\lib\site-packages\django\contrib\sessions\backends\db.py", line 34, in _get_session_from_db
    return self.model.objects.get(
  File "C:\Local Disk E\BlitzTech Systems\erpdev\venv\lib\site-packages\django\db\models\manager.py", line 87, in manager_method
    return getattr(self.get_queryset(), name)(*args, **kwargs)
  File "C:\Local Disk E\BlitzTech Systems\erpdev\venv\lib\site-packages\django\db\models\query.py", line 645, in get
    num = len(clone)
  File "C:\Local Disk E\BlitzTech Systems\erpdev\venv\lib\site-packages\django\db\models\query.py", line 382, in __len__
    self._fetch_all()
  File "C:\Local Disk E\BlitzTech Systems\erpdev\venv\lib\site-packages\django\db\models\query.py", line 1928, in _fetch_all
    self._result_cache = list(self._iterable_class(self))
  File "C:\Local Disk E\BlitzTech Systems\erpdev\venv\lib\site-packages\django\db\models\query.py", line 91, in __iter__
    results = compiler.execute_sql(
  File "C:\Local Disk E\BlitzTech Systems\erpdev\venv\lib\site-packages\django\db\models\sql\compiler.py", line 1572, in execute_sql
    cursor = self.connection.cursor()
  File "C:\Local Disk E\BlitzTech Systems\erpdev\venv\lib\site-packages\django\utils\asyncio.py", line 26, in inner
    return func(*args, **kwargs)
  File "C:\Local Disk E\BlitzTech Systems\erpdev\venv\lib\site-packages\django\db\backends\base\base.py", line 320, in cursor
    return self._cursor()
  File "C:\Local Disk E\BlitzTech Systems\erpdev\venv\lib\site-packages\django\db\backends\base\base.py", line 296, in _cursor
    self.ensure_connection()
  File "C:\Local Disk E\BlitzTech Systems\erpdev\venv\lib\site-packages\django\utils\asyncio.py", line 26, in inner
    return func(*args, **kwargs)
  File "C:\Local Disk E\BlitzTech Systems\erpdev\venv\lib\site-packages\django\db\backends\base\base.py", line 278, in ensure_connection
    with self.wrap_database_errors:
  File "C:\Local Disk E\BlitzTech Systems\erpdev\venv\lib\site-packages\django\db\utils.py", line 91, in __exit__
    raise dj_exc_value.with_traceback(traceback) from exc_value
  File "C:\Local Disk E\BlitzTech Systems\erpdev\venv\lib\site-packages\django\db\backends\base\base.py", line 279, in ensure_connection
    self.connect()
  File "C:\Local Disk E\BlitzTech Systems\erpdev\venv\lib\site-packages\django\utils\asyncio.py", line 26, in inner
    return func(*args, **kwargs)
  File "C:\Local Disk E\BlitzTech Systems\erpdev\venv\lib\site-packages\django\db\backends\base\base.py", line 256, in connect
    self.connection = self.get_new_connection(conn_params)
  File "C:\Local Disk E\BlitzTech Systems\erpdev\venv\lib\site-packages\django\utils\asyncio.py", line 26, in inner
    return func(*args, **kwargs)
  File "C:\Local Disk E\BlitzTech Systems\erpdev\venv\lib\site-packages\django\db\backends\postgresql\base.py", line 332, in get_new_connection
    connection = self.Database.connect(**conn_params)
  File "C:\Local Disk E\BlitzTech Systems\erpdev\venv\lib\site-packages\psycopg2\__init__.py", line 122, in connect
    conn = _connect(dsn, connection_factory=connection_factory, **kwasync)
django.db.utils.OperationalError: connection to server at "localhost" (::1), port 5432 failed: Connection refused (0x0000274D/10061)
	Is the server running on that host and accepting TCP/IP connections?
connection to server at "localhost" (127.0.0.1), port 5432 failed: Connection refused (0x0000274D/10061)
	Is the server running on that host and accepting TCP/IP connections?

ERROR 2025-08-28 17:23:58,257 log 2288 5032 Internal Server Error: /inventory/
Traceback (most recent call last):
  File "C:\Local Disk E\BlitzTech Systems\erpdev\venv\lib\site-packages\django\contrib\sessions\backends\base.py", line 244, in _get_session
    return self._session_cache
AttributeError: 'SessionStore' object has no attribute '_session_cache'

During handling of the above exception, another exception occurred:

Traceback (most recent call last):
  File "C:\Local Disk E\BlitzTech Systems\erpdev\venv\lib\site-packages\django\db\backends\base\base.py", line 279, in ensure_connection
    self.connect()
  File "C:\Local Disk E\BlitzTech Systems\erpdev\venv\lib\site-packages\django\utils\asyncio.py", line 26, in inner
    return func(*args, **kwargs)
  File "C:\Local Disk E\BlitzTech Systems\erpdev\venv\lib\site-packages\django\db\backends\base\base.py", line 256, in connect
    self.connection = self.get_new_connection(conn_params)
  File "C:\Local Disk E\BlitzTech Systems\erpdev\venv\lib\site-packages\django\utils\asyncio.py", line 26, in inner
    return func(*args, **kwargs)
  File "C:\Local Disk E\BlitzTech Systems\erpdev\venv\lib\site-packages\django\db\backends\postgresql\base.py", line 332, in get_new_connection
    connection = self.Database.connect(**conn_params)
  File "C:\Local Disk E\BlitzTech Systems\erpdev\venv\lib\site-packages\psycopg2\__init__.py", line 122, in connect
    conn = _connect(dsn, connection_factory=connection_factory, **kwasync)
psycopg2.OperationalError: connection to server at "localhost" (::1), port 5432 failed: Connection refused (0x0000274D/10061)
	Is the server running on that host and accepting TCP/IP connections?
connection to server at "localhost" (127.0.0.1), port 5432 failed: Connection refused (0x0000274D/10061)
	Is the server running on that host and accepting TCP/IP connections?


The above exception was the direct cause of the following exception:

Traceback (most recent call last):
  File "C:\Local Disk E\BlitzTech Systems\erpdev\venv\lib\site-packages\django\core\handlers\exception.py", line 55, in inner
    response = get_response(request)
  File "C:\Local Disk E\BlitzTech Systems\erpdev\venv\lib\site-packages\django\core\handlers\base.py", line 197, in _get_response
    response = wrapped_callback(request, *callback_args, **callback_kwargs)
  File "C:\Local Disk E\BlitzTech Systems\erpdev\venv\lib\site-packages\django\views\generic\base.py", line 104, in view
    return self.dispatch(request, *args, **kwargs)
  File "C:\Local Disk E\BlitzTech Systems\erpdev\venv\lib\site-packages\django\utils\decorators.py", line 48, in _wrapper
    return bound_method(*args, **kwargs)
  File "C:\Local Disk E\BlitzTech Systems\erpdev\venv\lib\site-packages\django\contrib\auth\decorators.py", line 57, in _view_wrapper
    test_pass = test_func(request.user)
  File "C:\Local Disk E\BlitzTech Systems\erpdev\venv\lib\site-packages\django\contrib\auth\decorators.py", line 80, in <lambda>
    lambda u: u.is_authenticated,
  File "C:\Local Disk E\BlitzTech Systems\erpdev\venv\lib\site-packages\django\utils\functional.py", line 251, in inner
    self._setup()
  File "C:\Local Disk E\BlitzTech Systems\erpdev\venv\lib\site-packages\django\utils\functional.py", line 404, in _setup
    self._wrapped = self._setupfunc()
  File "C:\Local Disk E\BlitzTech Systems\erpdev\venv\lib\site-packages\django\contrib\auth\middleware.py", line 37, in <lambda>
    request.user = SimpleLazyObject(lambda: get_user(request))
  File "C:\Local Disk E\BlitzTech Systems\erpdev\venv\lib\site-packages\django\contrib\auth\middleware.py", line 17, in get_user
    request._cached_user = auth.get_user(request)
  File "C:\Local Disk E\BlitzTech Systems\erpdev\venv\lib\site-packages\django\contrib\auth\__init__.py", line 209, in get_user
    user_id = _get_user_session_key(request)
  File "C:\Local Disk E\BlitzTech Systems\erpdev\venv\lib\site-packages\django\contrib\auth\__init__.py", line 62, in _get_user_session_key
    return get_user_model()._meta.pk.to_python(request.session[SESSION_KEY])
  File "C:\Local Disk E\BlitzTech Systems\erpdev\venv\lib\site-packages\django\contrib\sessions\backends\base.py", line 55, in __getitem__
    return self._session[key]
  File "C:\Local Disk E\BlitzTech Systems\erpdev\venv\lib\site-packages\django\contrib\sessions\backends\base.py", line 249, in _get_session
    self._session_cache = self.load()
  File "C:\Local Disk E\BlitzTech Systems\erpdev\venv\lib\site-packages\django\contrib\sessions\backends\db.py", line 55, in load
    s = self._get_session_from_db()
  File "C:\Local Disk E\BlitzTech Systems\erpdev\venv\lib\site-packages\django\contrib\sessions\backends\db.py", line 34, in _get_session_from_db
    return self.model.objects.get(
  File "C:\Local Disk E\BlitzTech Systems\erpdev\venv\lib\site-packages\django\db\models\manager.py", line 87, in manager_method
    return getattr(self.get_queryset(), name)(*args, **kwargs)
  File "C:\Local Disk E\BlitzTech Systems\erpdev\venv\lib\site-packages\django\db\models\query.py", line 645, in get
    num = len(clone)
  File "C:\Local Disk E\BlitzTech Systems\erpdev\venv\lib\site-packages\django\db\models\query.py", line 382, in __len__
    self._fetch_all()
  File "C:\Local Disk E\BlitzTech Systems\erpdev\venv\lib\site-packages\django\db\models\query.py", line 1928, in _fetch_all
    self._result_cache = list(self._iterable_class(self))
  File "C:\Local Disk E\BlitzTech Systems\erpdev\venv\lib\site-packages\django\db\models\query.py", line 91, in __iter__
    results = compiler.execute_sql(
  File "C:\Local Disk E\BlitzTech Systems\erpdev\venv\lib\site-packages\django\db\models\sql\compiler.py", line 1572, in execute_sql
    cursor = self.connection.cursor()
  File "C:\Local Disk E\BlitzTech Systems\erpdev\venv\lib\site-packages\django\utils\asyncio.py", line 26, in inner
    return func(*args, **kwargs)
  File "C:\Local Disk E\BlitzTech Systems\erpdev\venv\lib\site-packages\django\db\backends\base\base.py", line 320, in cursor
    return self._cursor()
  File "C:\Local Disk E\BlitzTech Systems\erpdev\venv\lib\site-packages\django\db\backends\base\base.py", line 296, in _cursor
    self.ensure_connection()
  File "C:\Local Disk E\BlitzTech Systems\erpdev\venv\lib\site-packages\django\utils\asyncio.py", line 26, in inner
    return func(*args, **kwargs)
  File "C:\Local Disk E\BlitzTech Systems\erpdev\venv\lib\site-packages\django\db\backends\base\base.py", line 278, in ensure_connection
    with self.wrap_database_errors:
  File "C:\Local Disk E\BlitzTech Systems\erpdev\venv\lib\site-packages\django\db\utils.py", line 91, in __exit__
    raise dj_exc_value.with_traceback(traceback) from exc_value
  File "C:\Local Disk E\BlitzTech Systems\erpdev\venv\lib\site-packages\django\db\backends\base\base.py", line 279, in ensure_connection
    self.connect()
  File "C:\Local Disk E\BlitzTech Systems\erpdev\venv\lib\site-packages\django\utils\asyncio.py", line 26, in inner
    return func(*args, **kwargs)
  File "C:\Local Disk E\BlitzTech Systems\erpdev\venv\lib\site-packages\django\db\backends\base\base.py", line 256, in connect
    self.connection = self.get_new_connection(conn_params)
  File "C:\Local Disk E\BlitzTech Systems\erpdev\venv\lib\site-packages\django\utils\asyncio.py", line 26, in inner
    return func(*args, **kwargs)
  File "C:\Local Disk E\BlitzTech Systems\erpdev\venv\lib\site-packages\django\db\backends\postgresql\base.py", line 332, in get_new_connection
    connection = self.Database.connect(**conn_params)
  File "C:\Local Disk E\BlitzTech Systems\erpdev\venv\lib\site-packages\psycopg2\__init__.py", line 122, in connect
    conn = _connect(dsn, connection_factory=connection_factory, **kwasync)
django.db.utils.OperationalError: connection to server at "localhost" (::1), port 5432 failed: Connection refused (0x0000274D/10061)
	Is the server running on that host and accepting TCP/IP connections?
connection to server at "localhost" (127.0.0.1), port 5432 failed: Connection refused (0x0000274D/10061)
	Is the server running on that host and accepting TCP/IP connections?

ERROR 2025-08-28 17:24:26,809 log 2288 5032 Internal Server Error: /inventory/
Traceback (most recent call last):
  File "C:\Local Disk E\BlitzTech Systems\erpdev\venv\lib\site-packages\django\contrib\sessions\backends\base.py", line 244, in _get_session
    return self._session_cache
AttributeError: 'SessionStore' object has no attribute '_session_cache'

During handling of the above exception, another exception occurred:

Traceback (most recent call last):
  File "C:\Local Disk E\BlitzTech Systems\erpdev\venv\lib\site-packages\django\db\backends\base\base.py", line 279, in ensure_connection
    self.connect()
  File "C:\Local Disk E\BlitzTech Systems\erpdev\venv\lib\site-packages\django\utils\asyncio.py", line 26, in inner
    return func(*args, **kwargs)
  File "C:\Local Disk E\BlitzTech Systems\erpdev\venv\lib\site-packages\django\db\backends\base\base.py", line 256, in connect
    self.connection = self.get_new_connection(conn_params)
  File "C:\Local Disk E\BlitzTech Systems\erpdev\venv\lib\site-packages\django\utils\asyncio.py", line 26, in inner
    return func(*args, **kwargs)
  File "C:\Local Disk E\BlitzTech Systems\erpdev\venv\lib\site-packages\django\db\backends\postgresql\base.py", line 332, in get_new_connection
    connection = self.Database.connect(**conn_params)
  File "C:\Local Disk E\BlitzTech Systems\erpdev\venv\lib\site-packages\psycopg2\__init__.py", line 122, in connect
    conn = _connect(dsn, connection_factory=connection_factory, **kwasync)
psycopg2.OperationalError: connection to server at "localhost" (::1), port 5432 failed: Connection refused (0x0000274D/10061)
	Is the server running on that host and accepting TCP/IP connections?
connection to server at "localhost" (127.0.0.1), port 5432 failed: Connection refused (0x0000274D/10061)
	Is the server running on that host and accepting TCP/IP connections?


The above exception was the direct cause of the following exception:

Traceback (most recent call last):
  File "C:\Local Disk E\BlitzTech Systems\erpdev\venv\lib\site-packages\django\core\handlers\exception.py", line 55, in inner
    response = get_response(request)
  File "C:\Local Disk E\BlitzTech Systems\erpdev\venv\lib\site-packages\django\utils\deprecation.py", line 131, in __call__
    response = self.process_response(request, response)
  File "C:\Local Disk E\BlitzTech Systems\erpdev\venv\lib\site-packages\django\contrib\sessions\middleware.py", line 48, in process_response
    if request.session.get_expire_at_browser_close():
  File "C:\Local Disk E\BlitzTech Systems\erpdev\venv\lib\site-packages\django\contrib\sessions\backends\base.py", line 403, in get_expire_at_browser_close
    if (expiry := self.get("_session_expiry")) is None:
  File "C:\Local Disk E\BlitzTech Systems\erpdev\venv\lib\site-packages\django\contrib\sessions\backends\base.py", line 74, in get
    return self._session.get(key, default)
  File "C:\Local Disk E\BlitzTech Systems\erpdev\venv\lib\site-packages\django\contrib\sessions\backends\base.py", line 249, in _get_session
    self._session_cache = self.load()
  File "C:\Local Disk E\BlitzTech Systems\erpdev\venv\lib\site-packages\django\contrib\sessions\backends\db.py", line 55, in load
    s = self._get_session_from_db()
  File "C:\Local Disk E\BlitzTech Systems\erpdev\venv\lib\site-packages\django\contrib\sessions\backends\db.py", line 34, in _get_session_from_db
    return self.model.objects.get(
  File "C:\Local Disk E\BlitzTech Systems\erpdev\venv\lib\site-packages\django\db\models\manager.py", line 87, in manager_method
    return getattr(self.get_queryset(), name)(*args, **kwargs)
  File "C:\Local Disk E\BlitzTech Systems\erpdev\venv\lib\site-packages\django\db\models\query.py", line 645, in get
    num = len(clone)
  File "C:\Local Disk E\BlitzTech Systems\erpdev\venv\lib\site-packages\django\db\models\query.py", line 382, in __len__
    self._fetch_all()
  File "C:\Local Disk E\BlitzTech Systems\erpdev\venv\lib\site-packages\django\db\models\query.py", line 1928, in _fetch_all
    self._result_cache = list(self._iterable_class(self))
  File "C:\Local Disk E\BlitzTech Systems\erpdev\venv\lib\site-packages\django\db\models\query.py", line 91, in __iter__
    results = compiler.execute_sql(
  File "C:\Local Disk E\BlitzTech Systems\erpdev\venv\lib\site-packages\django\db\models\sql\compiler.py", line 1572, in execute_sql
    cursor = self.connection.cursor()
  File "C:\Local Disk E\BlitzTech Systems\erpdev\venv\lib\site-packages\django\utils\asyncio.py", line 26, in inner
    return func(*args, **kwargs)
  File "C:\Local Disk E\BlitzTech Systems\erpdev\venv\lib\site-packages\django\db\backends\base\base.py", line 320, in cursor
    return self._cursor()
  File "C:\Local Disk E\BlitzTech Systems\erpdev\venv\lib\site-packages\django\db\backends\base\base.py", line 296, in _cursor
    self.ensure_connection()
  File "C:\Local Disk E\BlitzTech Systems\erpdev\venv\lib\site-packages\django\utils\asyncio.py", line 26, in inner
    return func(*args, **kwargs)
  File "C:\Local Disk E\BlitzTech Systems\erpdev\venv\lib\site-packages\django\db\backends\base\base.py", line 278, in ensure_connection
    with self.wrap_database_errors:
  File "C:\Local Disk E\BlitzTech Systems\erpdev\venv\lib\site-packages\django\db\utils.py", line 91, in __exit__
    raise dj_exc_value.with_traceback(traceback) from exc_value
  File "C:\Local Disk E\BlitzTech Systems\erpdev\venv\lib\site-packages\django\db\backends\base\base.py", line 279, in ensure_connection
    self.connect()
  File "C:\Local Disk E\BlitzTech Systems\erpdev\venv\lib\site-packages\django\utils\asyncio.py", line 26, in inner
    return func(*args, **kwargs)
  File "C:\Local Disk E\BlitzTech Systems\erpdev\venv\lib\site-packages\django\db\backends\base\base.py", line 256, in connect
    self.connection = self.get_new_connection(conn_params)
  File "C:\Local Disk E\BlitzTech Systems\erpdev\venv\lib\site-packages\django\utils\asyncio.py", line 26, in inner
    return func(*args, **kwargs)
  File "C:\Local Disk E\BlitzTech Systems\erpdev\venv\lib\site-packages\django\db\backends\postgresql\base.py", line 332, in get_new_connection
    connection = self.Database.connect(**conn_params)
  File "C:\Local Disk E\BlitzTech Systems\erpdev\venv\lib\site-packages\psycopg2\__init__.py", line 122, in connect
    conn = _connect(dsn, connection_factory=connection_factory, **kwasync)
django.db.utils.OperationalError: connection to server at "localhost" (::1), port 5432 failed: Connection refused (0x0000274D/10061)
	Is the server running on that host and accepting TCP/IP connections?
connection to server at "localhost" (127.0.0.1), port 5432 failed: Connection refused (0x0000274D/10061)
	Is the server running on that host and accepting TCP/IP connections?

ERROR 2025-08-28 17:24:31,824 log 2288 45200 Internal Server Error: /auth/api/dashboard-stats/
Traceback (most recent call last):
  File "C:\Local Disk E\BlitzTech Systems\erpdev\venv\lib\site-packages\django\contrib\sessions\backends\base.py", line 244, in _get_session
    return self._session_cache
AttributeError: 'SessionStore' object has no attribute '_session_cache'

During handling of the above exception, another exception occurred:

Traceback (most recent call last):
  File "C:\Local Disk E\BlitzTech Systems\erpdev\venv\lib\site-packages\django\db\backends\base\base.py", line 279, in ensure_connection
    self.connect()
  File "C:\Local Disk E\BlitzTech Systems\erpdev\venv\lib\site-packages\django\utils\asyncio.py", line 26, in inner
    return func(*args, **kwargs)
  File "C:\Local Disk E\BlitzTech Systems\erpdev\venv\lib\site-packages\django\db\backends\base\base.py", line 256, in connect
    self.connection = self.get_new_connection(conn_params)
  File "C:\Local Disk E\BlitzTech Systems\erpdev\venv\lib\site-packages\django\utils\asyncio.py", line 26, in inner
    return func(*args, **kwargs)
  File "C:\Local Disk E\BlitzTech Systems\erpdev\venv\lib\site-packages\django\db\backends\postgresql\base.py", line 332, in get_new_connection
    connection = self.Database.connect(**conn_params)
  File "C:\Local Disk E\BlitzTech Systems\erpdev\venv\lib\site-packages\psycopg2\__init__.py", line 122, in connect
    conn = _connect(dsn, connection_factory=connection_factory, **kwasync)
psycopg2.OperationalError: connection to server at "localhost" (::1), port 5432 failed: Connection refused (0x0000274D/10061)
	Is the server running on that host and accepting TCP/IP connections?
connection to server at "localhost" (127.0.0.1), port 5432 failed: Connection refused (0x0000274D/10061)
	Is the server running on that host and accepting TCP/IP connections?


The above exception was the direct cause of the following exception:

Traceback (most recent call last):
  File "C:\Local Disk E\BlitzTech Systems\erpdev\venv\lib\site-packages\django\core\handlers\exception.py", line 55, in inner
    response = get_response(request)
  File "C:\Local Disk E\BlitzTech Systems\erpdev\venv\lib\site-packages\django\utils\deprecation.py", line 131, in __call__
    response = self.process_response(request, response)
  File "C:\Local Disk E\BlitzTech Systems\erpdev\venv\lib\site-packages\django\contrib\sessions\middleware.py", line 48, in process_response
    if request.session.get_expire_at_browser_close():
  File "C:\Local Disk E\BlitzTech Systems\erpdev\venv\lib\site-packages\django\contrib\sessions\backends\base.py", line 403, in get_expire_at_browser_close
    if (expiry := self.get("_session_expiry")) is None:
  File "C:\Local Disk E\BlitzTech Systems\erpdev\venv\lib\site-packages\django\contrib\sessions\backends\base.py", line 74, in get
    return self._session.get(key, default)
  File "C:\Local Disk E\BlitzTech Systems\erpdev\venv\lib\site-packages\django\contrib\sessions\backends\base.py", line 249, in _get_session
    self._session_cache = self.load()
  File "C:\Local Disk E\BlitzTech Systems\erpdev\venv\lib\site-packages\django\contrib\sessions\backends\db.py", line 55, in load
    s = self._get_session_from_db()
  File "C:\Local Disk E\BlitzTech Systems\erpdev\venv\lib\site-packages\django\contrib\sessions\backends\db.py", line 34, in _get_session_from_db
    return self.model.objects.get(
  File "C:\Local Disk E\BlitzTech Systems\erpdev\venv\lib\site-packages\django\db\models\manager.py", line 87, in manager_method
    return getattr(self.get_queryset(), name)(*args, **kwargs)
  File "C:\Local Disk E\BlitzTech Systems\erpdev\venv\lib\site-packages\django\db\models\query.py", line 645, in get
    num = len(clone)
  File "C:\Local Disk E\BlitzTech Systems\erpdev\venv\lib\site-packages\django\db\models\query.py", line 382, in __len__
    self._fetch_all()
  File "C:\Local Disk E\BlitzTech Systems\erpdev\venv\lib\site-packages\django\db\models\query.py", line 1928, in _fetch_all
    self._result_cache = list(self._iterable_class(self))
  File "C:\Local Disk E\BlitzTech Systems\erpdev\venv\lib\site-packages\django\db\models\query.py", line 91, in __iter__
    results = compiler.execute_sql(
  File "C:\Local Disk E\BlitzTech Systems\erpdev\venv\lib\site-packages\django\db\models\sql\compiler.py", line 1572, in execute_sql
    cursor = self.connection.cursor()
  File "C:\Local Disk E\BlitzTech Systems\erpdev\venv\lib\site-packages\django\utils\asyncio.py", line 26, in inner
    return func(*args, **kwargs)
  File "C:\Local Disk E\BlitzTech Systems\erpdev\venv\lib\site-packages\django\db\backends\base\base.py", line 320, in cursor
    return self._cursor()
  File "C:\Local Disk E\BlitzTech Systems\erpdev\venv\lib\site-packages\django\db\backends\base\base.py", line 296, in _cursor
    self.ensure_connection()
  File "C:\Local Disk E\BlitzTech Systems\erpdev\venv\lib\site-packages\django\utils\asyncio.py", line 26, in inner
    return func(*args, **kwargs)
  File "C:\Local Disk E\BlitzTech Systems\erpdev\venv\lib\site-packages\django\db\backends\base\base.py", line 278, in ensure_connection
    with self.wrap_database_errors:
  File "C:\Local Disk E\BlitzTech Systems\erpdev\venv\lib\site-packages\django\db\utils.py", line 91, in __exit__
    raise dj_exc_value.with_traceback(traceback) from exc_value
  File "C:\Local Disk E\BlitzTech Systems\erpdev\venv\lib\site-packages\django\db\backends\base\base.py", line 279, in ensure_connection
    self.connect()
  File "C:\Local Disk E\BlitzTech Systems\erpdev\venv\lib\site-packages\django\utils\asyncio.py", line 26, in inner
    return func(*args, **kwargs)
  File "C:\Local Disk E\BlitzTech Systems\erpdev\venv\lib\site-packages\django\db\backends\base\base.py", line 256, in connect
    self.connection = self.get_new_connection(conn_params)
  File "C:\Local Disk E\BlitzTech Systems\erpdev\venv\lib\site-packages\django\utils\asyncio.py", line 26, in inner
    return func(*args, **kwargs)
  File "C:\Local Disk E\BlitzTech Systems\erpdev\venv\lib\site-packages\django\db\backends\postgresql\base.py", line 332, in get_new_connection
    connection = self.Database.connect(**conn_params)
  File "C:\Local Disk E\BlitzTech Systems\erpdev\venv\lib\site-packages\psycopg2\__init__.py", line 122, in connect
    conn = _connect(dsn, connection_factory=connection_factory, **kwasync)
django.db.utils.OperationalError: connection to server at "localhost" (::1), port 5432 failed: Connection refused (0x0000274D/10061)
	Is the server running on that host and accepting TCP/IP connections?
connection to server at "localhost" (127.0.0.1), port 5432 failed: Connection refused (0x0000274D/10061)
	Is the server running on that host and accepting TCP/IP connections?

ERROR 2025-08-28 17:24:31,906 log 2288 45324 Internal Server Error: /auth/api/get-notification-count/
Traceback (most recent call last):
  File "C:\Local Disk E\BlitzTech Systems\erpdev\venv\lib\site-packages\django\contrib\sessions\backends\base.py", line 244, in _get_session
    return self._session_cache
AttributeError: 'SessionStore' object has no attribute '_session_cache'

During handling of the above exception, another exception occurred:

Traceback (most recent call last):
  File "C:\Local Disk E\BlitzTech Systems\erpdev\venv\lib\site-packages\django\db\backends\base\base.py", line 279, in ensure_connection
    self.connect()
  File "C:\Local Disk E\BlitzTech Systems\erpdev\venv\lib\site-packages\django\utils\asyncio.py", line 26, in inner
    return func(*args, **kwargs)
  File "C:\Local Disk E\BlitzTech Systems\erpdev\venv\lib\site-packages\django\db\backends\base\base.py", line 256, in connect
    self.connection = self.get_new_connection(conn_params)
  File "C:\Local Disk E\BlitzTech Systems\erpdev\venv\lib\site-packages\django\utils\asyncio.py", line 26, in inner
    return func(*args, **kwargs)
  File "C:\Local Disk E\BlitzTech Systems\erpdev\venv\lib\site-packages\django\db\backends\postgresql\base.py", line 332, in get_new_connection
    connection = self.Database.connect(**conn_params)
  File "C:\Local Disk E\BlitzTech Systems\erpdev\venv\lib\site-packages\psycopg2\__init__.py", line 122, in connect
    conn = _connect(dsn, connection_factory=connection_factory, **kwasync)
psycopg2.OperationalError: connection to server at "localhost" (::1), port 5432 failed: Connection refused (0x0000274D/10061)
	Is the server running on that host and accepting TCP/IP connections?
connection to server at "localhost" (127.0.0.1), port 5432 failed: Connection refused (0x0000274D/10061)
	Is the server running on that host and accepting TCP/IP connections?


The above exception was the direct cause of the following exception:

Traceback (most recent call last):
  File "C:\Local Disk E\BlitzTech Systems\erpdev\venv\lib\site-packages\django\core\handlers\exception.py", line 55, in inner
    response = get_response(request)
  File "C:\Local Disk E\BlitzTech Systems\erpdev\venv\lib\site-packages\django\utils\deprecation.py", line 131, in __call__
    response = self.process_response(request, response)
  File "C:\Local Disk E\BlitzTech Systems\erpdev\venv\lib\site-packages\django\contrib\sessions\middleware.py", line 48, in process_response
    if request.session.get_expire_at_browser_close():
  File "C:\Local Disk E\BlitzTech Systems\erpdev\venv\lib\site-packages\django\contrib\sessions\backends\base.py", line 403, in get_expire_at_browser_close
    if (expiry := self.get("_session_expiry")) is None:
  File "C:\Local Disk E\BlitzTech Systems\erpdev\venv\lib\site-packages\django\contrib\sessions\backends\base.py", line 74, in get
    return self._session.get(key, default)
  File "C:\Local Disk E\BlitzTech Systems\erpdev\venv\lib\site-packages\django\contrib\sessions\backends\base.py", line 249, in _get_session
    self._session_cache = self.load()
  File "C:\Local Disk E\BlitzTech Systems\erpdev\venv\lib\site-packages\django\contrib\sessions\backends\db.py", line 55, in load
    s = self._get_session_from_db()
  File "C:\Local Disk E\BlitzTech Systems\erpdev\venv\lib\site-packages\django\contrib\sessions\backends\db.py", line 34, in _get_session_from_db
    return self.model.objects.get(
  File "C:\Local Disk E\BlitzTech Systems\erpdev\venv\lib\site-packages\django\db\models\manager.py", line 87, in manager_method
    return getattr(self.get_queryset(), name)(*args, **kwargs)
  File "C:\Local Disk E\BlitzTech Systems\erpdev\venv\lib\site-packages\django\db\models\query.py", line 645, in get
    num = len(clone)
  File "C:\Local Disk E\BlitzTech Systems\erpdev\venv\lib\site-packages\django\db\models\query.py", line 382, in __len__
    self._fetch_all()
  File "C:\Local Disk E\BlitzTech Systems\erpdev\venv\lib\site-packages\django\db\models\query.py", line 1928, in _fetch_all
    self._result_cache = list(self._iterable_class(self))
  File "C:\Local Disk E\BlitzTech Systems\erpdev\venv\lib\site-packages\django\db\models\query.py", line 91, in __iter__
    results = compiler.execute_sql(
  File "C:\Local Disk E\BlitzTech Systems\erpdev\venv\lib\site-packages\django\db\models\sql\compiler.py", line 1572, in execute_sql
    cursor = self.connection.cursor()
  File "C:\Local Disk E\BlitzTech Systems\erpdev\venv\lib\site-packages\django\utils\asyncio.py", line 26, in inner
    return func(*args, **kwargs)
  File "C:\Local Disk E\BlitzTech Systems\erpdev\venv\lib\site-packages\django\db\backends\base\base.py", line 320, in cursor
    return self._cursor()
  File "C:\Local Disk E\BlitzTech Systems\erpdev\venv\lib\site-packages\django\db\backends\base\base.py", line 296, in _cursor
    self.ensure_connection()
  File "C:\Local Disk E\BlitzTech Systems\erpdev\venv\lib\site-packages\django\utils\asyncio.py", line 26, in inner
    return func(*args, **kwargs)
  File "C:\Local Disk E\BlitzTech Systems\erpdev\venv\lib\site-packages\django\db\backends\base\base.py", line 278, in ensure_connection
    with self.wrap_database_errors:
  File "C:\Local Disk E\BlitzTech Systems\erpdev\venv\lib\site-packages\django\db\utils.py", line 91, in __exit__
    raise dj_exc_value.with_traceback(traceback) from exc_value
  File "C:\Local Disk E\BlitzTech Systems\erpdev\venv\lib\site-packages\django\db\backends\base\base.py", line 279, in ensure_connection
    self.connect()
  File "C:\Local Disk E\BlitzTech Systems\erpdev\venv\lib\site-packages\django\utils\asyncio.py", line 26, in inner
    return func(*args, **kwargs)
  File "C:\Local Disk E\BlitzTech Systems\erpdev\venv\lib\site-packages\django\db\backends\base\base.py", line 256, in connect
    self.connection = self.get_new_connection(conn_params)
  File "C:\Local Disk E\BlitzTech Systems\erpdev\venv\lib\site-packages\django\utils\asyncio.py", line 26, in inner
    return func(*args, **kwargs)
  File "C:\Local Disk E\BlitzTech Systems\erpdev\venv\lib\site-packages\django\db\backends\postgresql\base.py", line 332, in get_new_connection
    connection = self.Database.connect(**conn_params)
  File "C:\Local Disk E\BlitzTech Systems\erpdev\venv\lib\site-packages\psycopg2\__init__.py", line 122, in connect
    conn = _connect(dsn, connection_factory=connection_factory, **kwasync)
django.db.utils.OperationalError: connection to server at "localhost" (::1), port 5432 failed: Connection refused (0x0000274D/10061)
	Is the server running on that host and accepting TCP/IP connections?
connection to server at "localhost" (127.0.0.1), port 5432 failed: Connection refused (0x0000274D/10061)
	Is the server running on that host and accepting TCP/IP connections?

ERROR 2025-08-28 17:24:31,913 basehttp 2288 45200 "GET /auth/api/dashboard-stats/ HTTP/1.1" 500 237904
ERROR 2025-08-28 17:24:31,918 basehttp 2288 45324 "GET /auth/api/get-notification-count/ HTTP/1.1" 500 237977
WARNING 2025-08-28 17:29:03,538 log 2288 46336 Bad Request: /auth/api/get-notification-count/
WARNING 2025-08-28 17:29:03,540 log 2288 15900 Bad Request: /auth/api/dashboard-stats/
WARNING 2025-08-28 17:29:03,543 basehttp 2288 46336 "GET /auth/api/get-notification-count/ HTTP/1.1" 400 34
WARNING 2025-08-28 17:29:03,545 basehttp 2288 15900 "GET /auth/api/dashboard-stats/ HTTP/1.1" 400 34
WARNING 2025-08-28 17:29:27,622 log 2288 15900 Bad Request: /auth/api/get-notification-count/
WARNING 2025-08-28 17:29:27,625 basehttp 2288 15900 "GET /auth/api/get-notification-count/ HTTP/1.1" 400 34
WARNING 2025-08-28 17:29:43,297 log 2288 15900 Bad Request: /auth/api/get-notification-count/
WARNING 2025-08-28 17:29:43,299 basehttp 2288 15900 "GET /auth/api/get-notification-count/ HTTP/1.1" 400 34
INFO 2025-08-28 17:30:09,315 basehttp 2288 15900 "GET /inventory/ HTTP/1.1" 200 37473
INFO 2025-08-28 17:30:22,553 basehttp 2288 15900 "GET /inventory/products/create/ HTTP/1.1" 200 54500
WARNING 2025-08-28 17:30:25,403 log 2288 15900 Bad Request: /auth/api/get-notification-count/
WARNING 2025-08-28 17:30:25,405 basehttp 2288 15900 "GET /auth/api/get-notification-count/ HTTP/1.1" 400 34
WARNING 2025-08-28 17:30:25,562 log 2288 46336 Bad Request: /auth/api/get-notification-count/
WARNING 2025-08-28 17:30:25,565 basehttp 2288 46336 "GET /auth/api/get-notification-count/ HTTP/1.1" 400 34
ERROR 2025-08-28 17:30:26,475 log 2288 46336 Internal Server Error: /inventory/stock/adjust/
Traceback (most recent call last):
  File "C:\Local Disk E\BlitzTech Systems\erpdev\venv\lib\site-packages\django\core\handlers\exception.py", line 55, in inner
    response = get_response(request)
  File "C:\Local Disk E\BlitzTech Systems\erpdev\venv\lib\site-packages\django\utils\deprecation.py", line 131, in __call__
    response = self.process_response(request, response)
  File "C:\Local Disk E\BlitzTech Systems\erpdev\venv\lib\site-packages\django\middleware\clickjacking.py", line 27, in process_response
    if response.get("X-Frame-Options") is not None:
AttributeError: 'function' object has no attribute 'get'
ERROR 2025-08-28 17:30:26,479 basehttp 2288 46336 "GET /inventory/stock/adjust/ HTTP/1.1" 500 107240
WARNING 2025-08-28 17:30:29,755 log 2288 46336 Bad Request: /auth/api/get-notification-count/
WARNING 2025-08-28 17:30:29,757 basehttp 2288 46336 "GET /auth/api/get-notification-count/ HTTP/1.1" 400 34
WARNING 2025-08-28 17:30:29,913 log 2288 15900 Bad Request: /auth/api/get-notification-count/
WARNING 2025-08-28 17:30:29,916 basehttp 2288 15900 "GET /auth/api/get-notification-count/ HTTP/1.1" 400 34
ERROR 2025-08-28 17:30:30,794 log 2288 15900 Internal Server Error: /inventory/barcodes/scanner/
Traceback (most recent call last):
  File "C:\Local Disk E\BlitzTech Systems\erpdev\venv\lib\site-packages\django\core\handlers\exception.py", line 55, in inner
    response = get_response(request)
  File "C:\Local Disk E\BlitzTech Systems\erpdev\venv\lib\site-packages\django\core\handlers\base.py", line 220, in _get_response
    response = response.render()
  File "C:\Local Disk E\BlitzTech Systems\erpdev\venv\lib\site-packages\django\template\response.py", line 114, in render
    self.content = self.rendered_content
  File "C:\Local Disk E\BlitzTech Systems\erpdev\venv\lib\site-packages\django\template\response.py", line 90, in rendered_content
    template = self.resolve_template(self.template_name)
  File "C:\Local Disk E\BlitzTech Systems\erpdev\venv\lib\site-packages\django\template\response.py", line 72, in resolve_template
    return select_template(template, using=self.using)
  File "C:\Local Disk E\BlitzTech Systems\erpdev\venv\lib\site-packages\django\template\loader.py", line 47, in select_template
    raise TemplateDoesNotExist(", ".join(template_name_list), chain=chain)
django.template.exceptions.TemplateDoesNotExist: inventory/barcode/barcode_scanner.html
ERROR 2025-08-28 17:30:30,799 basehttp 2288 15900 "GET /inventory/barcodes/scanner/ HTTP/1.1" 500 128900
WARNING 2025-08-28 17:30:32,777 log 2288 15900 Bad Request: /auth/api/get-notification-count/
WARNING 2025-08-28 17:30:32,780 basehttp 2288 15900 "GET /auth/api/get-notification-count/ HTTP/1.1" 400 34
WARNING 2025-08-28 17:30:32,935 log 2288 46336 Bad Request: /auth/api/get-notification-count/
WARNING 2025-08-28 17:30:32,938 basehttp 2288 46336 "GET /auth/api/get-notification-count/ HTTP/1.1" 400 34
ERROR 2025-08-28 17:30:34,037 log 2288 46336 Internal Server Error: /inventory/products/bulk-import/
Traceback (most recent call last):
  File "C:\Local Disk E\BlitzTech Systems\erpdev\venv\lib\site-packages\django\core\handlers\exception.py", line 55, in inner
    response = get_response(request)
  File "C:\Local Disk E\BlitzTech Systems\erpdev\venv\lib\site-packages\django\utils\deprecation.py", line 131, in __call__
    response = self.process_response(request, response)
  File "C:\Local Disk E\BlitzTech Systems\erpdev\venv\lib\site-packages\django\middleware\clickjacking.py", line 27, in process_response
    if response.get("X-Frame-Options") is not None:
AttributeError: 'function' object has no attribute 'get'
ERROR 2025-08-28 17:30:34,041 basehttp 2288 46336 "GET /inventory/products/bulk-import/ HTTP/1.1" 500 107318
WARNING 2025-08-28 17:30:35,710 log 2288 46336 Bad Request: /auth/api/get-notification-count/
WARNING 2025-08-28 17:30:35,714 basehttp 2288 46336 "GET /auth/api/get-notification-count/ HTTP/1.1" 400 34
WARNING 2025-08-28 17:30:35,851 log 2288 15900 Bad Request: /auth/api/get-notification-count/
WARNING 2025-08-28 17:30:35,853 basehttp 2288 15900 "GET /auth/api/get-notification-count/ HTTP/1.1" 400 34
ERROR 2025-08-28 17:30:36,769 log 2288 15900 Internal Server Error: /inventory/reports/
Traceback (most recent call last):
  File "C:\Local Disk E\BlitzTech Systems\erpdev\venv\lib\site-packages\django\core\handlers\exception.py", line 55, in inner
    response = get_response(request)
  File "C:\Local Disk E\BlitzTech Systems\erpdev\venv\lib\site-packages\django\core\handlers\base.py", line 197, in _get_response
    response = wrapped_callback(request, *callback_args, **callback_kwargs)
  File "C:\Local Disk E\BlitzTech Systems\erpdev\venv\lib\site-packages\django\contrib\auth\decorators.py", line 60, in _view_wrapper
    return view_func(request, *args, **kwargs)
  File "C:\Local Disk E\BlitzTech Systems\erpdev\venv\lib\site-packages\django\contrib\auth\decorators.py", line 60, in _view_wrapper
    return view_func(request, *args, **kwargs)
  File "C:\Local Disk E\BlitzTech Systems\erpdev\inventory\decorators.py", line 75, in _wrapped_view
    return view_func(request, *args, **kwargs)
  File "C:\Local Disk E\BlitzTech Systems\erpdev\inventory\views.py", line 5069, in inventory_reports_view
    return render(request, 'inventory/reports.html', {
  File "C:\Local Disk E\BlitzTech Systems\erpdev\venv\lib\site-packages\django\shortcuts.py", line 25, in render
    content = loader.render_to_string(template_name, context, request, using=using)
  File "C:\Local Disk E\BlitzTech Systems\erpdev\venv\lib\site-packages\django\template\loader.py", line 61, in render_to_string
    template = get_template(template_name, using=using)
  File "C:\Local Disk E\BlitzTech Systems\erpdev\venv\lib\site-packages\django\template\loader.py", line 19, in get_template
    raise TemplateDoesNotExist(template_name, chain=chain)
django.template.exceptions.TemplateDoesNotExist: inventory/reports.html
ERROR 2025-08-28 17:30:36,777 basehttp 2288 15900 "GET /inventory/reports/ HTTP/1.1" 500 144923
WARNING 2025-08-28 17:30:38,676 log 2288 15900 Bad Request: /auth/api/get-notification-count/
WARNING 2025-08-28 17:30:38,678 basehttp 2288 15900 "GET /auth/api/get-notification-count/ HTTP/1.1" 400 34
WARNING 2025-08-28 17:30:38,810 log 2288 46336 Bad Request: /auth/api/get-notification-count/
WARNING 2025-08-28 17:30:38,813 basehttp 2288 46336 "GET /auth/api/get-notification-count/ HTTP/1.1" 400 34
INFO 2025-08-28 17:30:46,370 basehttp 2288 46336 "GET /auth/dashboard/ HTTP/1.1" 200 45644
INFO 2025-08-28 17:30:49,400 basehttp 2288 46336 "GET /crm/ HTTP/1.1" 200 44073
INFO 2025-08-28 17:30:52,526 basehttp 2288 46336 "GET /quotes/ HTTP/1.1" 200 33142
INFO 2025-08-28 17:30:55,135 basehttp 2288 46336 "GET /quotes/ HTTP/1.1" 200 33142
INFO 2025-08-28 17:30:55,966 basehttp 2288 46336 "GET /admin-dashboard/ HTTP/1.1" 200 45134
INFO 2025-08-28 17:30:59,019 basehttp 2288 46336 "GET /auth/employees/ HTTP/1.1" 200 54366
INFO 2025-08-28 17:31:02,393 basehttp 2288 46336 "GET /auth/users/ HTTP/1.1" 200 50224
INFO 2025-08-28 17:31:04,858 basehttp 2288 46336 "GET /auth/system-settings/ HTTP/1.1" 200 32816
INFO 2025-08-28 17:31:06,943 basehttp 2288 46336 "GET /auth/system-reports/ HTTP/1.1" 200 31943
INFO 2025-08-28 17:31:09,853 basehttp 2288 46336 "GET /inventory/ HTTP/1.1" 200 37473
INFO 2025-08-28 17:31:15,982 basehttp 2288 46336 "GET /inventory/products/create/ HTTP/1.1" 200 54500
INFO 2025-08-28 17:31:23,379 basehttp 2288 46336 "GET /inventory/products/ HTTP/1.1" 200 36870
INFO 2025-08-28 17:31:40,294 basehttp 2288 46336 "GET /admin/ HTTP/1.1" 200 43942
INFO 2025-08-28 17:31:45,315 basehttp 2288 46336 "GET /admin/inventory/supplier/ HTTP/1.1" 200 34218
INFO 2025-08-28 17:31:45,497 basehttp 2288 46336 "GET /admin/jsi18n/ HTTP/1.1" 200 3342
INFO 2025-08-28 17:31:49,183 basehttp 2288 46336 "GET /admin/ HTTP/1.1" 200 43942
WARNING 2025-08-28 17:31:50,735 log 2288 46336 Bad Request: /auth/api/get-notification-count/
WARNING 2025-08-28 17:31:50,739 basehttp 2288 46336 "GET /auth/api/get-notification-count/ HTTP/1.1" 400 34
ERROR 2025-08-28 17:32:02,721 log 2288 46336 Internal Server Error: /inventory/products/bulk-import/
Traceback (most recent call last):
  File "C:\Local Disk E\BlitzTech Systems\erpdev\venv\lib\site-packages\django\core\handlers\exception.py", line 55, in inner
    response = get_response(request)
  File "C:\Local Disk E\BlitzTech Systems\erpdev\venv\lib\site-packages\django\utils\deprecation.py", line 131, in __call__
    response = self.process_response(request, response)
  File "C:\Local Disk E\BlitzTech Systems\erpdev\venv\lib\site-packages\django\middleware\clickjacking.py", line 27, in process_response
    if response.get("X-Frame-Options") is not None:
AttributeError: 'function' object has no attribute 'get'
ERROR 2025-08-28 17:32:02,726 basehttp 2288 46336 "GET /inventory/products/bulk-import/ HTTP/1.1" 500 107327
WARNING 2025-08-28 17:32:04,339 log 2288 46336 Bad Request: /auth/api/get-notification-count/
WARNING 2025-08-28 17:32:04,344 basehttp 2288 46336 "GET /auth/api/get-notification-count/ HTTP/1.1" 400 34
WARNING 2025-08-28 17:32:04,517 log 2288 15900 Bad Request: /auth/api/get-notification-count/
WARNING 2025-08-28 17:32:04,522 basehttp 2288 15900 "GET /auth/api/get-notification-count/ HTTP/1.1" 400 34
INFO 2025-08-28 17:32:06,114 basehttp 2288 15900 "GET /inventory/products/export/ HTTP/1.1" 200 176
WARNING 2025-08-28 17:32:11,966 log 2288 15900 Bad Request: /auth/api/get-notification-count/
WARNING 2025-08-28 17:32:11,972 basehttp 2288 15900 "GET /auth/api/get-notification-count/ HTTP/1.1" 400 34
INFO 2025-08-28 17:32:14,131 basehttp 2288 15900 "GET /inventory/products/ HTTP/1.1" 200 36870
INFO 2025-08-28 17:32:16,969 basehttp 2288 15900 "GET /inventory/products/ HTTP/1.1" 200 36870
WARNING 2025-08-28 17:32:18,842 log 2288 15900 Bad Request: /auth/api/get-notification-count/
WARNING 2025-08-28 17:32:18,845 basehttp 2288 15900 "GET /auth/api/get-notification-count/ HTTP/1.1" 400 34
WARNING 2025-08-28 17:32:18,998 log 2288 46336 Bad Request: /auth/api/get-notification-count/
WARNING 2025-08-28 17:32:19,002 basehttp 2288 46336 "GET /auth/api/get-notification-count/ HTTP/1.1" 400 34
INFO 2025-08-28 17:32:20,249 basehttp 2288 46336 "GET /inventory/products/create/ HTTP/1.1" 200 54500
INFO 2025-08-28 17:32:31,849 basehttp 2288 46336 "GET /inventory/products/ HTTP/1.1" 200 36870
INFO 2025-08-28 17:33:20,248 basehttp 2288 46336 "GET /inventory/products/create/ HTTP/1.1" 200 54500
INFO 2025-08-28 17:33:49,999 basehttp 2288 46336 "GET /inventory/products/ HTTP/1.1" 200 36870
INFO 2025-08-28 17:33:52,083 basehttp 2288 46336 "GET /inventory/products/create/ HTTP/1.1" 200 54500
WARNING 2025-08-28 17:33:53,745 log 2288 46336 Bad Request: /auth/api/get-notification-count/
WARNING 2025-08-28 17:33:53,749 basehttp 2288 46336 "GET /auth/api/get-notification-count/ HTTP/1.1" 400 34
WARNING 2025-08-28 17:33:53,924 log 2288 15900 Bad Request: /auth/api/get-notification-count/
WARNING 2025-08-28 17:33:53,925 basehttp 2288 15900 "GET /auth/api/get-notification-count/ HTTP/1.1" 400 34
ERROR 2025-08-28 17:33:56,041 log 2288 15900 Internal Server Error: /inventory/products/bulk-import/
Traceback (most recent call last):
  File "C:\Local Disk E\BlitzTech Systems\erpdev\venv\lib\site-packages\django\core\handlers\exception.py", line 55, in inner
    response = get_response(request)
  File "C:\Local Disk E\BlitzTech Systems\erpdev\venv\lib\site-packages\django\utils\deprecation.py", line 131, in __call__
    response = self.process_response(request, response)
  File "C:\Local Disk E\BlitzTech Systems\erpdev\venv\lib\site-packages\django\middleware\clickjacking.py", line 27, in process_response
    if response.get("X-Frame-Options") is not None:
AttributeError: 'function' object has no attribute 'get'
ERROR 2025-08-28 17:33:56,045 basehttp 2288 15900 "GET /inventory/products/bulk-import/ HTTP/1.1" 500 107327
WARNING 2025-08-28 17:33:57,571 log 2288 15900 Bad Request: /auth/api/get-notification-count/
WARNING 2025-08-28 17:33:57,572 basehttp 2288 15900 "GET /auth/api/get-notification-count/ HTTP/1.1" 400 34
WARNING 2025-08-28 17:33:57,717 log 2288 46336 Bad Request: /auth/api/get-notification-count/
WARNING 2025-08-28 17:33:57,722 basehttp 2288 46336 "GET /auth/api/get-notification-count/ HTTP/1.1" 400 34
INFO 2025-08-28 17:33:59,286 basehttp 2288 46336 "GET /inventory/products/ HTTP/1.1" 200 36870
INFO 2025-08-28 17:34:02,278 basehttp 2288 46336 "GET /inventory/products/create/ HTTP/1.1" 200 54500
WARNING 2025-08-28 17:36:04,515 log 2288 40988 Bad Request: /auth/api/get-notification-count/
WARNING 2025-08-28 17:36:04,520 basehttp 2288 40988 "GET /auth/api/get-notification-count/ HTTP/1.1" 400 34
INFO 2025-08-28 17:36:39,110 basehttp 2288 40988 "GET /inventory/ HTTP/1.1" 200 37473
WARNING 2025-08-28 17:41:39,442 log 2288 40336 Bad Request: /auth/api/get-notification-count/
WARNING 2025-08-28 17:41:39,448 basehttp 2288 40336 "GET /auth/api/get-notification-count/ HTTP/1.1" 400 34
WARNING 2025-08-28 17:46:39,462 log 2288 40336 Bad Request: /auth/api/get-notification-count/
WARNING 2025-08-28 17:46:39,464 basehttp 2288 40336 "GET /auth/api/get-notification-count/ HTTP/1.1" 400 34
WARNING 2025-08-28 17:49:25,331 log 2288 16988 Bad Request: /auth/api/get-notification-count/
WARNING 2025-08-28 17:49:25,332 basehttp 2288 16988 "GET /auth/api/get-notification-count/ HTTP/1.1" 400 34
WARNING 2025-08-28 17:51:39,932 log 2288 16988 Bad Request: /auth/api/get-notification-count/
WARNING 2025-08-28 17:51:39,935 basehttp 2288 16988 "GET /auth/api/get-notification-count/ HTTP/1.1" 400 34
WARNING 2025-08-28 17:56:39,941 log 2288 16988 Bad Request: /auth/api/get-notification-count/
WARNING 2025-08-28 17:56:39,946 basehttp 2288 16988 "GET /auth/api/get-notification-count/ HTTP/1.1" 400 34
WARNING 2025-08-28 18:01:51,088 log 2288 34368 Bad Request: /auth/api/get-notification-count/
WARNING 2025-08-28 18:01:51,089 basehttp 2288 34368 "GET /auth/api/get-notification-count/ HTTP/1.1" 400 34
WARNING 2025-08-28 18:25:17,053 log 2288 20208 Bad Request: /auth/api/get-notification-count/
WARNING 2025-08-28 18:25:17,055 basehttp 2288 20208 "GET /auth/api/get-notification-count/ HTTP/1.1" 400 34
WARNING 2025-08-28 19:25:01,032 log 2288 11076 Bad Request: /auth/api/get-notification-count/
WARNING 2025-08-28 19:25:01,033 basehttp 2288 11076 "GET /auth/api/get-notification-count/ HTTP/1.1" 400 34
WARNING 2025-08-28 19:26:40,118 log 2288 14076 Bad Request: /auth/api/get-notification-count/
WARNING 2025-08-28 19:26:40,120 basehttp 2288 14076 "GET /auth/api/get-notification-count/ HTTP/1.1" 400 34
WARNING 2025-08-28 19:31:40,156 log 2288 14076 Bad Request: /auth/api/get-notification-count/
WARNING 2025-08-28 19:31:40,160 basehttp 2288 14076 "GET /auth/api/get-notification-count/ HTTP/1.1" 400 34
WARNING 2025-08-28 19:36:40,193 log 2288 14076 Bad Request: /auth/api/get-notification-count/
WARNING 2025-08-28 19:36:40,196 basehttp 2288 14076 "GET /auth/api/get-notification-count/ HTTP/1.1" 400 34
WARNING 2025-08-28 19:41:40,070 log 2288 14076 Bad Request: /auth/api/get-notification-count/
WARNING 2025-08-28 19:41:40,072 basehttp 2288 14076 "GET /auth/api/get-notification-count/ HTTP/1.1" 400 34
WARNING 2025-08-28 19:46:40,089 log 2288 14076 Bad Request: /auth/api/get-notification-count/
WARNING 2025-08-28 19:46:40,091 basehttp 2288 14076 "GET /auth/api/get-notification-count/ HTTP/1.1" 400 34
WARNING 2025-08-28 19:51:40,069 log 2288 14076 Bad Request: /auth/api/get-notification-count/
WARNING 2025-08-28 19:51:40,074 basehttp 2288 14076 "GET /auth/api/get-notification-count/ HTTP/1.1" 400 34
WARNING 2025-08-28 20:30:37,331 log 2288 37172 Bad Request: /auth/api/get-notification-count/
WARNING 2025-08-28 20:30:37,334 basehttp 2288 37172 "GET /auth/api/get-notification-count/ HTTP/1.1" 400 34
WARNING 2025-08-29 10:18:38,093 log 2288 45128 Bad Request: /auth/api/get-notification-count/
WARNING 2025-08-29 10:18:38,095 basehttp 2288 45128 "GET /auth/api/get-notification-count/ HTTP/1.1" 400 34
WARNING 2025-08-29 10:21:32,966 log 2288 50064 Bad Request: /auth/api/get-notification-count/
WARNING 2025-08-29 10:21:32,967 basehttp 2288 50064 "GET /auth/api/get-notification-count/ HTTP/1.1" 400 34
